Workbook

Sheet (현황표)
H1: MAX수치 순위 | I1: 구분 | J1: PAC | K1: SHO | L1: PAS | M1: DRI | N1: DEF | O1: PHY | P1: Acceleration | Q1: Sprint Speed | R1: Positioning | S1: Finishing | T1: Shot Power | U1: Long Shots | V1: Volleys | W1: Penalties | X1: Vision | Y1: Crossing | Z1: FK Accuracy | AA1: Short Passing | AB1: Long Passing | AC1: Curve | AD1: Agility | AE1: Balance | AF1: Reactions | AG1: Ball Control | AH1: Dribbling | AI1: Composure | AJ1: Interceptions | AK1: Heading Accuracy | AL1: Defensive Awareness | AM1: Standing Tackle | AN1: Sliding Tackle | AO1: Jumping | AP1: Stamina | AQ1: Strength | AR1: Aggression | AS1: SM | AT1: WF
H2: 1위 | I2: MAX | J2: 84 | K2: 82 | L2: 79 | M2: 84 | N2: 79 | P2: 87 | Q2: 87 | R2: 84 | S2: 88 | T2: 88 | U2: 84 | V2: 84 | W2: 83 | X2: 86 | Y2: 82 | AA2: 86 | AB2: 82 | AC2: 84 | AD2: 89 | AE2: 85 | AF2: 86 | AG2: 89 | AH2: 89 | AI2: 85 | AJ2: 76 | AK2: 75 | AL2: 80 | AM2: 80 | AN2: 75 | AO2: 78 | AP2: 83 | AQ2: 77 | AR2: 75 | AS2: 4 | AT2: 3
I3: +OVR | J3: 1 | K3: 1 | L3: 1 | M3: 1 | N3: 1 | P3: 1 | Q3: 1 | R3: 6 | S3: 1 | T3: 1 | U3: 1 | V3: 6 | W3: 6 | X3: 1 | Y3: 1 10 | AA3: 1 | AB3: 1 | AC3: 1 | AD3: 1 | AE3: 1 10 | AF3: 1 | AG3: 1 | AH3: 1 | AI3: 1 | AJ3: 34 | AK3: 1 | AL3: 40 | AM3: 40 | AN3: 40 34 | AO3: 10 | AP3: 1 | AQ3: 40 | AR3: 40 | AS3: 10 34 | AT3: 8
I4: +Stat Point | J4: 2 | K4: 1 | L4: 1 | M4: 2 | N4: 1 | P4: 3 | Q4: 3 | R4: 7 | S4: 4 | T4: 3 | U4: 3 | V4: 7 | W4: 7 | X4: 10 | Y4: 12 10 | AA4: 8 | AB4: 12 | AC4: 12 | AD4: 4 | AE4: 2 15 | AF4: 3 | AG4: 5 | AH4: 5 | AI4: 3 | AJ4: 40 | AK4: 2 | AL4: 40 | AM4: 40 | AN4: 40 | AO4: 10 | AP4: 1 | AQ4: 40 | AR4: 40 | AS4: 1 2 | AT4: 2
I5: 진화명 | J5: Frontline Flair - EA SPORTS FC 27 | K5: Frontline Flair - EA SPORTS FC 27 | L5: Midfield Polish [SP+ 1] - EA SPORTS FC 27 | M5: Frontline Flair - EA SPORTS FC 27 | N5: Midfield Polish [SP+ 1] - EA SPORTS FC 27 | P5: Future Stars Academy III - EA SPORTS FC 27 | Q5: Future Stars Academy III - EA SPORTS FC 27 | R5: Batigol Precision - EA SPORTS FC 27 | S5: Future Stars Academy III - EA SPORTS FC 27 | T5: Future Stars Academy III - EA SPORTS FC 27 | U5: Future Stars Academy III - EA SPORTS FC 27 | V5: Batigol Precision - EA SPORTS FC 27 | W5: Batigol Precision - EA SPORTS FC 27 | X5: Future Stars Academy II - EA SPORTS FC 27 | Y5: Future Stars Academy II - EA SPORTS FC 27 Winger Glow Up [SP+ 26] - EA SPORTS FC 27 | AA5: Future Stars Academy II - EA SPORTS FC 27 | AB5: Future Stars Academy II - EA SPORTS FC 27 | AC5: Future Stars Academy II - EA SPORTS FC 27 | AD5: Future Stars Academy III - EA SPORTS FC 27 | AE5: Future Stars Academy III - EA SPORTS FC 27 Winger Glow Up [SP+ 26] - EA SPORTS FC 27 | AF5: Future Stars Academy III - EA SPORTS FC 27 | AG5: Future Stars Academy III - EA SPORTS FC 27 | AH5: Future Stars Academy III - EA SPORTS FC 27 | AI5: Future Stars Academy III - EA SPORTS FC 27 | AJ5: Intro to Evolutions - EA SPORTS FC 27 | AK5: Future Stars Academy II - EA SPORTS FC 27 | AL5: Midfield Glow Up - EA SPORTS FC 27 | AM5: Midfield Glow Up - EA SPORTS FC 27 | AN5: Midfield Glow Up - EA SPORTS FC 27 Intro to Evolutions - EA SPORTS FC 27 | AO5: Striker Glow Up [SP 7] - EA SPORTS FC 27 | AP5: Future Stars Academy II - EA SPORTS FC 27 | AQ5: Midfield Glow Up - EA SPORTS FC 27 | AR5: Midfield Glow Up - EA SPORTS FC 27 | AS5: Touchline Magic - EA SPORTS FC 27 Future Stars Academy I - EA SPORTS FC 27 | AT5: Repeat Delivery - EA SPORTS FC 27
H6: 2위 | I6: MAX | P6: 85 | Q6: 85 | R6: 82 | S6: 83 | T6: 84 | U6: 83 | V6: 82 | W6: 81 | X6: 84 | Y6: 79 | AA6: 83 | AB6: 81 | AC6: 83 | AD6: 86 | AE6: 83 | AF6: 83 | AG6: 85 | AH6: 84 | AI6: 84 | AJ6: 75 | AK6: 73 | AL6: 77 | AM6: 78 | AO6: 76 | AP6: 82 | AQ6: 73 | AS6: 3
I7: +OVR | P7: 10 | Q7: 10 | R7: 10 | S7: 6 10 | T7: 6 | U7: 6 | V7: 1 | W7: 40 | X7: 8 | Y7: 40 | AA7: 1 | AB7: 40 | AC7: 10 | AD7: 10 | AE7: 10 | AF7: 10 | AG7: 10 | AH7: 10 | AI7: 1 | AJ7: 40 | AK7: 34 | AL7: 34 | AM7: 34 | AO7: 40 | AP7: 10 34 | AQ7: 34 | AS7: 40 10 8
I8: +Stat Point | P8: 10 15 | Q8: 10 15 | R8: 15 | S8: 7 15 | T8: 7 | U8: 7 | V8: 5 | W8: 50 | X8: 15 | Y8: 50 | AA8: 4 | AB8: 50 | AC8: 7 | AD8: 15 | AE8: 10 | AF8: 10 | AG8: 15 | AH8: 10 15 | AI8: 3 | AJ8: 40 | AK8: 20 | AL8: 40 | AM8: 40 | AO8: 40 | AP8: 7 25 | AQ8: 15 | AS8: 2 1
I9: 진화명 | P9: Touchline Magic - EA SPORTS FC 27 Winger Glow Up [SP+ 26] - EA SPORTS FC 27 | Q9: Touchline Magic - EA SPORTS FC 27 Winger Glow Up [SP+ 26] - EA SPORTS FC 27 | R9: Striker Glow Up [SP 7] - EA SPORTS FC 27 | S9: Batigol Precision - EA SPORTS FC 27 Striker Glow Up [SP 7] - EA SPORTS FC 27 | T9: Batigol Precision - EA SPORTS FC 27 | U9: Batigol Precision - EA SPORTS FC 27 | V9: Future Stars Academy III - EA SPORTS FC 27 | W9: Nine Duty - EA SPORTS FC 27 | X9: Repeat Delivery - EA SPORTS FC 27 | Y9: Playmaker Reborn - EA SPORTS FC 27 | AA9: Believe - EA SPORTS FC 27 | AB9: Playmaker Reborn - EA SPORTS FC 27 | AC9: Touchline Magic - EA SPORTS FC 27 | AD9: Winger Glow Up [SP+ 26] - EA SPORTS FC 27 | AE9: Touchline Magic - EA SPORTS FC 27 | AF9: Touchline Magic - EA SPORTS FC 27 | AG9: Winger Glow Up [SP+ 26] - EA SPORTS FC 27 | AH9: Touchline Magic - EA SPORTS FC 27 Winger Glow Up [SP+ 26] - EA SPORTS FC 27 | AI9: Believe - EA SPORTS FC 27 | AJ9: Midfield Glow Up - EA SPORTS FC 27 | AK9: Future Stars Academy I - EA SPORTS FC 27 | AL9: Intro to Evolutions - EA SPORTS FC 27 | AM9: Intro to Evolutions - EA SPORTS FC 27 | AO9: Midfield Glow Up - EA SPORTS FC 27 | AP9: Touchline Magic - EA SPORTS FC 27 Future Stars Academy I - EA SPORTS FC 27 | AQ9: Future Stars Academy I - EA SPORTS FC 27 | AS9: Nine Duty - EA SPORTS FC 27 Winger Glow Up [SP+ 26] - EA SPORTS FC 27 Repeat Delivery - EA SPORTS FC 27
H10: 3위 | I10: MAX | P10: 83 | Q10: 83 | R10: 81 | S10: 82 | T10: 82 | U10: 81 | V10: 79 | W10: 77 | X10: 82 | Y10: 78 | AA10: 82 | AB10: 80 | AC10: 80 | AD10: 84 | AE10: 81 | AF10: 82 | AG10: 84 | AH10: 81 | AI10: 83 | AP10: 80
I11: +OVR | P11: 6 | Q11: 6 | R11: 10 1 | S11: 10 | T11: 10 | U11: 10 | V11: 40 | W11: 40 | X11: 34 | Y11: 34 8 | AA11: 34 | AB11: 10 | AC11: 34 | AD11: 10 | AE11: 6 | AF11: 1 6 | AG11: 10 | AH11: 1 6 | AI11: 10 | AP11: 34
I12: +Stat Point | P12: 7 | Q12: 7 | R12: 7 1 | S12: 7 | T12: 15 | U12: 7 | V12: 50 | W12: 40 | X12: 30 | Y12: 40 10 | AA12: 35 | AB12: 10 | AC12: 40 | AD12: 10 | AE12: 7 | AF12: 2 7 | AG12: 10 | AH12: 1 7 | AI12: 10 | AP12: 40
I13: 진화명 | P13: Batigol Precision - EA SPORTS FC 27 | Q13: Batigol Precision - EA SPORTS FC 27 | R13: Touchline Magic - EA SPORTS FC 27 Future Stars Academy II - EA SPORTS FC 27 | S13: Touchline Magic - EA SPORTS FC 27 | T13: Striker Glow Up [SP 7] - EA SPORTS FC 27 | U13: Touchline Magic - EA SPORTS FC 27 | V13: Nine Duty - EA SPORTS FC 27 | W13: Playmaker Reborn - EA SPORTS FC 27 | X13: Future Stars Academy I - EA SPORTS FC 27 | Y13: Intro to Evolutions - EA SPORTS FC 27 Repeat Delivery - EA SPORTS FC 27 | AA13: Future Stars Academy I - EA SPORTS FC 27 | AB13: Winger Glow Up [SP+ 26] - EA SPORTS FC 27 | AC13: Intro to Evolutions - EA SPORTS FC 27 | AD13: Touchline Magic - EA SPORTS FC 27 | AE13: Batigol Precision - EA SPORTS FC 27 | AF13: Future Stars Academy II - EA SPORTS FC 27 Batigol Precision - EA SPORTS FC 27 | AG13: Touchline Magic - EA SPORTS FC 27 | AH13: Future Stars Academy II - EA SPORTS FC 27 Batigol Precision - EA SPORTS FC 27 | AI13: Touchline Magic - EA SPORTS FC 27 | AP13: Intro to Evolutions - EA SPORTS FC 27
J27: 선택한 스탯의 Max값 | K27: 진화명 | L27: Rank | M27: +OVR | N27: Max OVR | O27: 포지션 제한 | P27: OVR 제한 | Q27: 기타 요구조건 | AB27: 상위 Max값
J28: 84 | K28: Frontline Flair - EA SPORTS FC 27 | L28: 1 | M28: 1 | N28: 84 | O28: LW, RW, ST | P28: Max 83 | Q28: Overall Max. 83 Position LW, RW, ST Excluded Position CAM Max PS 7 Pace Max. 84 Details Submit by in 9 days Expiry in 16 days Coins Cost Free Points Cost Free | AB28: =MAX($J$28:$J$322)
AB29: =_xlfn.MAXIFS($J$28:$J$322,$J$28:$J$322,"<"&AB28)
AB30: =_xlfn.MAXIFS($J$28:$J$322,$J$28:$J$322,"<"&AB29)
J328: {=IFERROR(INDEX(Unified_Matrix!$A:$ZZ,ROW(A325),MATCH("Max "&$J$9,Unified_Matrix!$1:$1,0)),"")} | K328: {=IFERROR(INDEX(Unified_Matrix!$A:$ZZ,ROW(A325),MATCH("Evolution_Name",Unified_Matrix!$1:$1,0)),"")} | L328: =IF(J328="","",IF(J328=0,"",IF(J328=$AB$28,1,IF(J328=$AB$29,2,IF(J328=$AB$30,3,""))))) | M328: {=IFERROR(INDEX(Unified_Matrix!$A:$ZZ,ROW(A325),MATCH("+ OVR",Unified_Matrix!$1:$1,0)),"")} | N328: {=IFERROR(INDEX(Unified_Matrix!$A:$ZZ,ROW(A325),MATCH("Max OVR",Unified_Matrix!$1:$1,0)),"")} | O328: {=IFERROR(INDEX(Unified_Matrix!$A:$ZZ,ROW(A325),MATCH("Req_Position",Unified_Matrix!$1:$1,0)),"")} | P328: {=IFERROR(INDEX(Unified_Matrix!$A:$ZZ,ROW(A325),MATCH("Req_OVR_Max",Unified_Matrix!$1:$1,0)),"")} | Q328: {=IFERROR(INDEX(Unified_Matrix!$A:$ZZ,ROW(A325),MATCH("Req_Other",Unified_Matrix!$1:$1,0)),"")}
J329: {=IFERROR(INDEX(Unified_Matrix!$A:$ZZ,ROW(A326),MATCH("Max "&$J$9,Unified_Matrix!$1:$1,0)),"")} | K329: {=IFERROR(INDEX(Unified_Matrix!$A:$ZZ,ROW(A326),MATCH("Evolution_Name",Unified_Matrix!$1:$1,0)),"")} | L329: =IF(J329="","",IF(J329=0,"",IF(J329=$AB$28,1,IF(J329=$AB$29,2,IF(J329=$AB$30,3,""))))) | M329: {=IFERROR(INDEX(Unified_Matrix!$A:$ZZ,ROW(A326),MATCH("+ OVR",Unified_Matrix!$1:$1,0)),"")} | N329: {=IFERROR(INDEX(Unified_Matrix!$A:$ZZ,ROW(A326),MATCH("Max OVR",Unified_Matrix!$1:$1,0)),"")} | O329: {=IFERROR(INDEX(Unified_Matrix!$A:$ZZ,ROW(A326),MATCH("Req_Position",Unified_Matrix!$1:$1,0)),"")} | P329: {=IFERROR(INDEX(Unified_Matrix!$A:$ZZ,ROW(A326),MATCH("Req_OVR_Max",Unified_Matrix!$1:$1,0)),"")} | Q329: {=IFERROR(INDEX(Unified_Matrix!$A:$ZZ,ROW(A326),MATCH("Req_Other",Unified_Matrix!$1:$1,0)),"")}
J330: {=IFERROR(INDEX(Unified_Matrix!$A:$ZZ,ROW(A327),MATCH("Max "&$J$9,Unified_Matrix!$1:$1,0)),"")} | K330: {=IFERROR(INDEX(Unified_Matrix!$A:$ZZ,ROW(A327),MATCH("Evolution_Name",Unified_Matrix!$1:$1,0)),"")} | L330: =IF(J330="","",IF(J330=0,"",IF(J330=$AB$28,1,IF(J330=$AB$29,2,IF(J330=$AB$30,3,""))))) | M330: {=IFERROR(INDEX(Unified_Matrix!$A:$ZZ,ROW(A327),MATCH("+ OVR",Unified_Matrix!$1:$1,0)),"")} | N330: {=IFERROR(INDEX(Unified_Matrix!$A:$ZZ,ROW(A327),MATCH("Max OVR",Unified_Matrix!$1:$1,0)),"")} | O330: {=IFERROR(INDEX(Unified_Matrix!$A:$ZZ,ROW(A327),MATCH("Req_Position",Unified_Matrix!$1:$1,0)),"")} | P330: {=IFERROR(INDEX(Unified_Matrix!$A:$ZZ,ROW(A327),MATCH("Req_OVR_Max",Unified_Matrix!$1:$1,0)),"")} | Q330: {=IFERROR(INDEX(Unified_Matrix!$A:$ZZ,ROW(A327),MATCH("Req_Other",Unified_Matrix!$1:$1,0)),"")}
J331: {=IFERROR(INDEX(Unified_Matrix!$A:$ZZ,ROW(A328),MATCH("Max "&$J$9,Unified_Matrix!$1:$1,0)),"")} | K331: {=IFERROR(INDEX(Unified_Matrix!$A:$ZZ,ROW(A328),MATCH("Evolution_Name",Unified_Matrix!$1:$1,0)),"")} | L331: =IF(J331="","",IF(J331=0,"",IF(J331=$AB$28,1,IF(J331=$AB$29,2,IF(J331=$AB$30,3,""))))) | M331: {=IFERROR(INDEX(Unified_Matrix!$A:$ZZ,ROW(A328),MATCH("+ OVR",Unified_Matrix!$1:$1,0)),"")} | N331: {=IFERROR(INDEX(Unified_Matrix!$A:$ZZ,ROW(A328),MATCH("Max OVR",Unified_Matrix!$1:$1,0)),"")} | O331: {=IFERROR(INDEX(Unified_Matrix!$A:$ZZ,ROW(A328),MATCH("Req_Position",Unified_Matrix!$1:$1,0)),"")} | P331: {=IFERROR(INDEX(Unified_Matrix!$A:$ZZ,ROW(A328),MATCH("Req_OVR_Max",Unified_Matrix!$1:$1,0)),"")} | Q331: {=IFERROR(INDEX(Unified_Matrix!$A:$ZZ,ROW(A328),MATCH("Req_Other",Unified_Matrix!$1:$1,0)),"")}
J332: {=IFERROR(INDEX(Unified_Matrix!$A:$ZZ,ROW(A329),MATCH("Max "&$J$9,Unified_Matrix!$1:$1,0)),"")} | K332: {=IFERROR(INDEX(Unified_Matrix!$A:$ZZ,ROW(A329),MATCH("Evolution_Name",Unified_Matrix!$1:$1,0)),"")} | L332: =IF(J332="","",IF(J332=0,"",IF(J332=$AB$28,1,IF(J332=$AB$29,2,IF(J332=$AB$30,3,""))))) | M332: {=IFERROR(INDEX(Unified_Matrix!$A:$ZZ,ROW(A329),MATCH("+ OVR",Unified_Matrix!$1:$1,0)),"")} | N332: {=IFERROR(INDEX(Unified_Matrix!$A:$ZZ,ROW(A329),MATCH("Max OVR",Unified_Matrix!$1:$1,0)),"")} | O332: {=IFERROR(INDEX(Unified_Matrix!$A:$ZZ,ROW(A329),MATCH("Req_Position",Unified_Matrix!$1:$1,0)),"")} | P332: {=IFERROR(INDEX(Unified_Matrix!$A:$ZZ,ROW(A329),MATCH("Req_OVR_Max",Unified_Matrix!$1:$1,0)),"")} | Q332: {=IFERROR(INDEX(Unified_Matrix!$A:$ZZ,ROW(A329),MATCH("Req_Other",Unified_Matrix!$1:$1,0)),"")}
J333: {=IFERROR(INDEX(Unified_Matrix!$A:$ZZ,ROW(A330),MATCH("Max "&$J$9,Unified_Matrix!$1:$1,0)),"")} | K333: {=IFERROR(INDEX(Unified_Matrix!$A:$ZZ,ROW(A330),MATCH("Evolution_Name",Unified_Matrix!$1:$1,0)),"")} | L333: =IF(J333="","",IF(J333=0,"",IF(J333=$AB$28,1,IF(J333=$AB$29,2,IF(J333=$AB$30,3,""))))) | M333: {=IFERROR(INDEX(Unified_Matrix!$A:$ZZ,ROW(A330),MATCH("+ OVR",Unified_Matrix!$1:$1,0)),"")} | N333: {=IFERROR(INDEX(Unified_Matrix!$A:$ZZ,ROW(A330),MATCH("Max OVR",Unified_Matrix!$1:$1,0)),"")} | O333: {=IFERROR(INDEX(Unified_Matrix!$A:$ZZ,ROW(A330),MATCH("Req_Position",Unified_Matrix!$1:$1,0)),"")} | P333: {=IFERROR(INDEX(Unified_Matrix!$A:$ZZ,ROW(A330),MATCH("Req_OVR_Max",Unified_Matrix!$1:$1,0)),"")} | Q333: {=IFERROR(INDEX(Unified_Matrix!$A:$ZZ,ROW(A330),MATCH("Req_Other",Unified_Matrix!$1:$1,0)),"")}
J334: {=IFERROR(INDEX(Unified_Matrix!$A:$ZZ,ROW(A331),MATCH("Max "&$J$9,Unified_Matrix!$1:$1,0)),"")} | K334: {=IFERROR(INDEX(Unified_Matrix!$A:$ZZ,ROW(A331),MATCH("Evolution_Name",Unified_Matrix!$1:$1,0)),"")} | L334: =IF(J334="","",IF(J334=0,"",IF(J334=$AB$28,1,IF(J334=$AB$29,2,IF(J334=$AB$30,3,""))))) | M334: {=IFERROR(INDEX(Unified_Matrix!$A:$ZZ,ROW(A331),MATCH("+ OVR",Unified_Matrix!$1:$1,0)),"")} | N334: {=IFERROR(INDEX(Unified_Matrix!$A:$ZZ,ROW(A331),MATCH("Max OVR",Unified_Matrix!$1:$1,0)),"")} | O334: {=IFERROR(INDEX(Unified_Matrix!$A:$ZZ,ROW(A331),MATCH("Req_Position",Unified_Matrix!$1:$1,0)),"")} | P334: {=IFERROR(INDEX(Unified_Matrix!$A:$ZZ,ROW(A331),MATCH("Req_OVR_Max",Unified_Matrix!$1:$1,0)),"")} | Q334: {=IFERROR(INDEX(Unified_Matrix!$A:$ZZ,ROW(A331),MATCH("Req_Other",Unified_Matrix!$1:$1,0)),"")}
J335: {=IFERROR(INDEX(Unified_Matrix!$A:$ZZ,ROW(A332),MATCH("Max "&$J$9,Unified_Matrix!$1:$1,0)),"")} | K335: {=IFERROR(INDEX(Unified_Matrix!$A:$ZZ,ROW(A332),MATCH("Evolution_Name",Unified_Matrix!$1:$1,0)),"")} | L335: =IF(J335="","",IF(J335=0,"",IF(J335=$AB$28,1,IF(J335=$AB$29,2,IF(J335=$AB$30,3,""))))) | M335: {=IFERROR(INDEX(Unified_Matrix!$A:$ZZ,ROW(A332),MATCH("+ OVR",Unified_Matrix!$1:$1,0)),"")} | N335: {=IFERROR(INDEX(Unified_Matrix!$A:$ZZ,ROW(A332),MATCH("Max OVR",Unified_Matrix!$1:$1,0)),"")} | O335: {=IFERROR(INDEX(Unified_Matrix!$A:$ZZ,ROW(A332),MATCH("Req_Position",Unified_Matrix!$1:$1,0)),"")} | P335: {=IFERROR(INDEX(Unified_Matrix!$A:$ZZ,ROW(A332),MATCH("Req_OVR_Max",Unified_Matrix!$1:$1,0)),"")} | Q335: {=IFERROR(INDEX(Unified_Matrix!$A:$ZZ,ROW(A332),MATCH("Req_Other",Unified_Matrix!$1:$1,0)),"")}
J336: {=IFERROR(INDEX(Unified_Matrix!$A:$ZZ,ROW(A333),MATCH("Max "&$J$9,Unified_Matrix!$1:$1,0)),"")} | K336: {=IFERROR(INDEX(Unified_Matrix!$A:$ZZ,ROW(A333),MATCH("Evolution_Name",Unified_Matrix!$1:$1,0)),"")} | L336: =IF(J336="","",IF(J336=0,"",IF(J336=$AB$28,1,IF(J336=$AB$29,2,IF(J336=$AB$30,3,""))))) | M336: {=IFERROR(INDEX(Unified_Matrix!$A:$ZZ,ROW(A333),MATCH("+ OVR",Unified_Matrix!$1:$1,0)),"")} | N336: {=IFERROR(INDEX(Unified_Matrix!$A:$ZZ,ROW(A333),MATCH("Max OVR",Unified_Matrix!$1:$1,0)),"")} | O336: {=IFERROR(INDEX(Unified_Matrix!$A:$ZZ,ROW(A333),MATCH("Req_Position",Unified_Matrix!$1:$1,0)),"")} | P336: {=IFERROR(INDEX(Unified_Matrix!$A:$ZZ,ROW(A333),MATCH("Req_OVR_Max",Unified_Matrix!$1:$1,0)),"")} | Q336: {=IFERROR(INDEX(Unified_Matrix!$A:$ZZ,ROW(A333),MATCH("Req_Other",Unified_Matrix!$1:$1,0)),"")}
J337: {=IFERROR(INDEX(Unified_Matrix!$A:$ZZ,ROW(A334),MATCH("Max "&$J$9,Unified_Matrix!$1:$1,0)),"")} | K337: {=IFERROR(INDEX(Unified_Matrix!$A:$ZZ,ROW(A334),MATCH("Evolution_Name",Unified_Matrix!$1:$1,0)),"")} | L337: =IF(J337="","",IF(J337=0,"",IF(J337=$AB$28,1,IF(J337=$AB$29,2,IF(J337=$AB$30,3,""))))) | M337: {=IFERROR(INDEX(Unified_Matrix!$A:$ZZ,ROW(A334),MATCH("+ OVR",Unified_Matrix!$1:$1,0)),"")} | N337: {=IFERROR(INDEX(Unified_Matrix!$A:$ZZ,ROW(A334),MATCH("Max OVR",Unified_Matrix!$1:$1,0)),"")} | O337: {=IFERROR(INDEX(Unified_Matrix!$A:$ZZ,ROW(A334),MATCH("Req_Position",Unified_Matrix!$1:$1,0)),"")} | P337: {=IFERROR(INDEX(Unified_Matrix!$A:$ZZ,ROW(A334),MATCH("Req_OVR_Max",Unified_Matrix!$1:$1,0)),"")} | Q337: {=IFERROR(INDEX(Unified_Matrix!$A:$ZZ,ROW(A334),MATCH("Req_Other",Unified_Matrix!$1:$1,0)),"")}
J338: {=IFERROR(INDEX(Unified_Matrix!$A:$ZZ,ROW(A335),MATCH("Max "&$J$9,Unified_Matrix!$1:$1,0)),"")} | K338: {=IFERROR(INDEX(Unified_Matrix!$A:$ZZ,ROW(A335),MATCH("Evolution_Name",Unified_Matrix!$1:$1,0)),"")} | L338: =IF(J338="","",IF(J338=0,"",IF(J338=$AB$28,1,IF(J338=$AB$29,2,IF(J338=$AB$30,3,""))))) | M338: {=IFERROR(INDEX(Unified_Matrix!$A:$ZZ,ROW(A335),MATCH("+ OVR",Unified_Matrix!$1:$1,0)),"")} | N338: {=IFERROR(INDEX(Unified_Matrix!$A:$ZZ,ROW(A335),MATCH("Max OVR",Unified_Matrix!$1:$1,0)),"")} | O338: {=IFERROR(INDEX(Unified_Matrix!$A:$ZZ,ROW(A335),MATCH("Req_Position",Unified_Matrix!$1:$1,0)),"")} | P338: {=IFERROR(INDEX(Unified_Matrix!$A:$ZZ,ROW(A335),MATCH("Req_OVR_Max",Unified_Matrix!$1:$1,0)),"")} | Q338: {=IFERROR(INDEX(Unified_Matrix!$A:$ZZ,ROW(A335),MATCH("Req_Other",Unified_Matrix!$1:$1,0)),"")}
J339: {=IFERROR(INDEX(Unified_Matrix!$A:$ZZ,ROW(A336),MATCH("Max "&$J$9,Unified_Matrix!$1:$1,0)),"")} | K339: {=IFERROR(INDEX(Unified_Matrix!$A:$ZZ,ROW(A336),MATCH("Evolution_Name",Unified_Matrix!$1:$1,0)),"")} | L339: =IF(J339="","",IF(J339=0,"",IF(J339=$AB$28,1,IF(J339=$AB$29,2,IF(J339=$AB$30,3,""))))) | M339: {=IFERROR(INDEX(Unified_Matrix!$A:$ZZ,ROW(A336),MATCH("+ OVR",Unified_Matrix!$1:$1,0)),"")} | N339: {=IFERROR(INDEX(Unified_Matrix!$A:$ZZ,ROW(A336),MATCH("Max OVR",Unified_Matrix!$1:$1,0)),"")} | O339: {=IFERROR(INDEX(Unified_Matrix!$A:$ZZ,ROW(A336),MATCH("Req_Position",Unified_Matrix!$1:$1,0)),"")} | P339: {=IFERROR(INDEX(Unified_Matrix!$A:$ZZ,ROW(A336),MATCH("Req_OVR_Max",Unified_Matrix!$1:$1,0)),"")} | Q339: {=IFERROR(INDEX(Unified_Matrix!$A:$ZZ,ROW(A336),MATCH("Req_Other",Unified_Matrix!$1:$1,0)),"")}
... J522: {=IFERROR(INDEX(Unified_Matrix!$A:$ZZ,ROW(A519),MATCH("Max "&$J$9,Unified_Matrix!$1:$1,0)),"")} | K522: {=IFERROR(INDEX(Unified_Matrix!$A:$ZZ,ROW(A519),MATCH("Evolution_Name",Unified_Matrix!$1:$1,0)),"")} | L522: =IF(J522="","",IF(J522=0,"",IF(J522=$AB$28,1,IF(J522=$AB$29,2,IF(J522=$AB$30,3,""))))) | M522: {=IFERROR(INDEX(Unified_Matrix!$A:$ZZ,ROW(A519),MATCH("+ OVR",Unified_Matrix!$1:$1,0)),"")} | N522: {=IFERROR(INDEX(Unified_Matrix!$A:$ZZ,ROW(A519),MATCH("Max OVR",Unified_Matrix!$1:$1,0)),"")} | O522: {=IFERROR(INDEX(Unified_Matrix!$A:$ZZ,ROW(A519),MATCH("Req_Position",Unified_Matrix!$1:$1,0)),"")} | P522: {=IFERROR(INDEX(Unified_Matrix!$A:$ZZ,ROW(A519),MATCH("Req_OVR_Max",Unified_Matrix!$1:$1,0)),"")} | Q522: {=IFERROR(INDEX(Unified_Matrix!$A:$ZZ,ROW(A519),MATCH("Req_Other",Unified_Matrix!$1:$1,0)),"")}

Sheet (분석시트)
F1: PAC | G1: SHO | H1: PAS | I1: DRI | J1: DEF | K1: PHY | L1: Acceleration | M1: Sprint Speed | N1: Positioning | O1: Finishing | P1: Shot Power | Q1: Long Shots | R1: Volleys | S1: Penalties | T1: Vision | U1: Crossing | V1: FK Accuracy | W1: Short Passing | X1: Long Passing | Y1: Curve | Z1: Agility | AA1: Balance | AB1: Reactions | AC1: Ball Control | AD1: Dribbling | AE1: Composure | AF1: Interceptions | AG1: Heading Accuracy | AH1: Defensive Awareness | AI1: Standing Tackle | AJ1: Sliding Tackle | AK1: Jumping | AL1: Stamina | AM1: Strength | AN1: Aggression | AO1: SM | AP1: WF
H3: Agility
F4: MAX수치 순위 | G4: 번호 | H4: 상한선 | I4: 진화명 | J4: +Stat Point | K4: +OVR | L4: MAX OVR | M4: 포지션 제한 | N4: OVR 제한 | O4: 기타 요구조건
F5: 1위 | G5: 1 | H5: =_xlfn.MAXIFS(INDIRECT("Evo[Max "&$H$3&"]"),INDIRECT("Evo[Max "&$H$3&"]"),">0") | I5: {=IFERROR(INDEX(Evo[Evolution_Name],_xlfn.AGGREGATE(15,6,(ROW(Evo[Evolution_Name])-MIN(ROW(Evo[Evolution_Name]))+1)/((INDIRECT("Evo[Max "&$H$3&"]")=$H5)*(INDIRECT("Evo[Max "&$H$3&"]")>0)),$G5)),"")} | J5: {=IFERROR(INDEX(INDIRECT("Evo[+ "&$H$3&"]"),_xlfn.AGGREGATE(15,6,(ROW(Evo[Evolution_Name])-MIN(ROW(Evo[Evolution_Name]))+1)/((INDIRECT("Evo[Max "&$H$3&"]")=$H5)*(INDIRECT("Evo[Max "&$H$3&"]")>0)),$G5)),"")} | K5: {=IFERROR(INDEX(INDIRECT("Evo[+ OVR]"),_xlfn.AGGREGATE(15,6,(ROW(Evo[Evolution_Name])-MIN(ROW(Evo[Evolution_Name]))+1)/((INDIRECT("Evo[Max "&$H$3&"]")=$H5)*(INDIRECT("Evo[Max "&$H$3&"]")>0)),$G5)),"")} | L5: {=IFERROR(INDEX(INDIRECT("Evo[Max OVR]"),_xlfn.AGGREGATE(15,6,(ROW(Evo[Evolution_Name])-MIN(ROW(Evo[Evolution_Name]))+1)/((INDIRECT("Evo[Max "&$H$3&"]")=$H5)*(INDIRECT("Evo[Max "&$H$3&"]")>0)),$G5)),"")} | M5: {=IFERROR(INDEX(INDIRECT("Evo[Req_Position]"),_xlfn.AGGREGATE(15,6,(ROW(Evo[Evolution_Name])-MIN(ROW(Evo[Evolution_Name]))+1)/((INDIRECT("Evo[Max "&$H$3&"]")=$H5)*(INDIRECT("Evo[Max "&$H$3&"]")>0)),$G5)),"")} | N5: {=IFERROR(INDEX(INDIRECT("Evo[Req_OVR_Max]"),_xlfn.AGGREGATE(15,6,(ROW(Evo[Evolution_Name])-MIN(ROW(Evo[Evolution_Name]))+1)/((INDIRECT("Evo[Max "&$H$3&"]")=$H5)*(INDIRECT("Evo[Max "&$H$3&"]")>0)),$G5)),"")} | O5: {=IFERROR(INDEX(INDIRECT("Evo[Req_Other]"),_xlfn.AGGREGATE(15,6,(ROW(Evo[Evolution_Name])-MIN(ROW(Evo[Evolution_Name]))+1)/((INDIRECT("Evo[Max "&$H$3&"]")=$H5)*(INDIRECT("Evo[Max "&$H$3&"]")>0)),$G5)),"")}
G6: 2 | H6: =_xlfn.MAXIFS(INDIRECT("Evo[Max "&$H$3&"]"),INDIRECT("Evo[Max "&$H$3&"]"),">0") | I6: {=IFERROR(INDEX(Evo[Evolution_Name],_xlfn.AGGREGATE(15,6,(ROW(Evo[Evolution_Name])-MIN(ROW(Evo[Evolution_Name]))+1)/((INDIRECT("Evo[Max "&$H$3&"]")=$H6)*(INDIRECT("Evo[Max "&$H$3&"]")>0)),$G6)),"")} | J6: {=IFERROR(INDEX(INDIRECT("Evo[+ "&$H$3&"]"),_xlfn.AGGREGATE(15,6,(ROW(Evo[Evolution_Name])-MIN(ROW(Evo[Evolution_Name]))+1)/((INDIRECT("Evo[Max "&$H$3&"]")=$H6)*(INDIRECT("Evo[Max "&$H$3&"]")>0)),$G6)),"")} | K6: {=IFERROR(INDEX(INDIRECT("Evo[+ OVR]"),_xlfn.AGGREGATE(15,6,(ROW(Evo[Evolution_Name])-MIN(ROW(Evo[Evolution_Name]))+1)/((INDIRECT("Evo[Max "&$H$3&"]")=$H6)*(INDIRECT("Evo[Max "&$H$3&"]")>0)),$G6)),"")} | L6: {=IFERROR(INDEX(INDIRECT("Evo[Max OVR]"),_xlfn.AGGREGATE(15,6,(ROW(Evo[Evolution_Name])-MIN(ROW(Evo[Evolution_Name]))+1)/((INDIRECT("Evo[Max "&$H$3&"]")=$H6)*(INDIRECT("Evo[Max "&$H$3&"]")>0)),$G6)),"")} | M6: {=IFERROR(INDEX(INDIRECT("Evo[Req_Position]"),_xlfn.AGGREGATE(15,6,(ROW(Evo[Evolution_Name])-MIN(ROW(Evo[Evolution_Name]))+1)/((INDIRECT("Evo[Max "&$H$3&"]")=$H6)*(INDIRECT("Evo[Max "&$H$3&"]")>0)),$G6)),"")} | N6: {=IFERROR(INDEX(INDIRECT("Evo[Req_OVR_Max]"),_xlfn.AGGREGATE(15,6,(ROW(Evo[Evolution_Name])-MIN(ROW(Evo[Evolution_Name]))+1)/((INDIRECT("Evo[Max "&$H$3&"]")=$H6)*(INDIRECT("Evo[Max "&$H$3&"]")>0)),$G6)),"")} | O6: {=IFERROR(INDEX(INDIRECT("Evo[Req_Other]"),_xlfn.AGGREGATE(15,6,(ROW(Evo[Evolution_Name])-MIN(ROW(Evo[Evolution_Name]))+1)/((INDIRECT("Evo[Max "&$H$3&"]")=$H6)*(INDIRECT("Evo[Max "&$H$3&"]")>0)),$G6)),"")}
G7: 3 | H7: =_xlfn.MAXIFS(INDIRECT("Evo[Max "&$H$3&"]"),INDIRECT("Evo[Max "&$H$3&"]"),">0") | I7: {=IFERROR(INDEX(Evo[Evolution_Name],_xlfn.AGGREGATE(15,6,(ROW(Evo[Evolution_Name])-MIN(ROW(Evo[Evolution_Name]))+1)/((INDIRECT("Evo[Max "&$H$3&"]")=$H7)*(INDIRECT("Evo[Max "&$H$3&"]")>0)),$G7)),"")} | J7: {=IFERROR(INDEX(INDIRECT("Evo[+ "&$H$3&"]"),_xlfn.AGGREGATE(15,6,(ROW(Evo[Evolution_Name])-MIN(ROW(Evo[Evolution_Name]))+1)/((INDIRECT("Evo[Max "&$H$3&"]")=$H7)*(INDIRECT("Evo[Max "&$H$3&"]")>0)),$G7)),"")} | K7: {=IFERROR(INDEX(INDIRECT("Evo[+ OVR]"),_xlfn.AGGREGATE(15,6,(ROW(Evo[Evolution_Name])-MIN(ROW(Evo[Evolution_Name]))+1)/((INDIRECT("Evo[Max "&$H$3&"]")=$H7)*(INDIRECT("Evo[Max "&$H$3&"]")>0)),$G7)),"")} | L7: {=IFERROR(INDEX(INDIRECT("Evo[Max OVR]"),_xlfn.AGGREGATE(15,6,(ROW(Evo[Evolution_Name])-MIN(ROW(Evo[Evolution_Name]))+1)/((INDIRECT("Evo[Max "&$H$3&"]")=$H7)*(INDIRECT("Evo[Max "&$H$3&"]")>0)),$G7)),"")} | M7: {=IFERROR(INDEX(INDIRECT("Evo[Req_Position]"),_xlfn.AGGREGATE(15,6,(ROW(Evo[Evolution_Name])-MIN(ROW(Evo[Evolution_Name]))+1)/((INDIRECT("Evo[Max "&$H$3&"]")=$H7)*(INDIRECT("Evo[Max "&$H$3&"]")>0)),$G7)),"")} | N7: {=IFERROR(INDEX(INDIRECT("Evo[Req_OVR_Max]"),_xlfn.AGGREGATE(15,6,(ROW(Evo[Evolution_Name])-MIN(ROW(Evo[Evolution_Name]))+1)/((INDIRECT("Evo[Max "&$H$3&"]")=$H7)*(INDIRECT("Evo[Max "&$H$3&"]")>0)),$G7)),"")} | O7: {=IFERROR(INDEX(INDIRECT("Evo[Req_Other]"),_xlfn.AGGREGATE(15,6,(ROW(Evo[Evolution_Name])-MIN(ROW(Evo[Evolution_Name]))+1)/((INDIRECT("Evo[Max "&$H$3&"]")=$H7)*(INDIRECT("Evo[Max "&$H$3&"]")>0)),$G7)),"")}
G8: 4 | H8: =_xlfn.MAXIFS(INDIRECT("Evo[Max "&$H$3&"]"),INDIRECT("Evo[Max "&$H$3&"]"),">0") | I8: {=IFERROR(INDEX(Evo[Evolution_Name],_xlfn.AGGREGATE(15,6,(ROW(Evo[Evolution_Name])-MIN(ROW(Evo[Evolution_Name]))+1)/((INDIRECT("Evo[Max "&$H$3&"]")=$H8)*(INDIRECT("Evo[Max "&$H$3&"]")>0)),$G8)),"")} | J8: {=IFERROR(INDEX(INDIRECT("Evo[+ "&$H$3&"]"),_xlfn.AGGREGATE(15,6,(ROW(Evo[Evolution_Name])-MIN(ROW(Evo[Evolution_Name]))+1)/((INDIRECT("Evo[Max "&$H$3&"]")=$H8)*(INDIRECT("Evo[Max "&$H$3&"]")>0)),$G8)),"")} | K8: {=IFERROR(INDEX(INDIRECT("Evo[+ OVR]"),_xlfn.AGGREGATE(15,6,(ROW(Evo[Evolution_Name])-MIN(ROW(Evo[Evolution_Name]))+1)/((INDIRECT("Evo[Max "&$H$3&"]")=$H8)*(INDIRECT("Evo[Max "&$H$3&"]")>0)),$G8)),"")} | L8: {=IFERROR(INDEX(INDIRECT("Evo[Max OVR]"),_xlfn.AGGREGATE(15,6,(ROW(Evo[Evolution_Name])-MIN(ROW(Evo[Evolution_Name]))+1)/((INDIRECT("Evo[Max "&$H$3&"]")=$H8)*(INDIRECT("Evo[Max "&$H$3&"]")>0)),$G8)),"")} | M8: {=IFERROR(INDEX(INDIRECT("Evo[Req_Position]"),_xlfn.AGGREGATE(15,6,(ROW(Evo[Evolution_Name])-MIN(ROW(Evo[Evolution_Name]))+1)/((INDIRECT("Evo[Max "&$H$3&"]")=$H8)*(INDIRECT("Evo[Max "&$H$3&"]")>0)),$G8)),"")} | N8: {=IFERROR(INDEX(INDIRECT("Evo[Req_OVR_Max]"),_xlfn.AGGREGATE(15,6,(ROW(Evo[Evolution_Name])-MIN(ROW(Evo[Evolution_Name]))+1)/((INDIRECT("Evo[Max "&$H$3&"]")=$H8)*(INDIRECT("Evo[Max "&$H$3&"]")>0)),$G8)),"")} | O8: {=IFERROR(INDEX(INDIRECT("Evo[Req_Other]"),_xlfn.AGGREGATE(15,6,(ROW(Evo[Evolution_Name])-MIN(ROW(Evo[Evolution_Name]))+1)/((INDIRECT("Evo[Max "&$H$3&"]")=$H8)*(INDIRECT("Evo[Max "&$H$3&"]")>0)),$G8)),"")}
G9: 5 | H9: =_xlfn.MAXIFS(INDIRECT("Evo[Max "&$H$3&"]"),INDIRECT("Evo[Max "&$H$3&"]"),">0") | I9: {=IFERROR(INDEX(Evo[Evolution_Name],_xlfn.AGGREGATE(15,6,(ROW(Evo[Evolution_Name])-MIN(ROW(Evo[Evolution_Name]))+1)/((INDIRECT("Evo[Max "&$H$3&"]")=$H9)*(INDIRECT("Evo[Max "&$H$3&"]")>0)),$G9)),"")} | J9: {=IFERROR(INDEX(INDIRECT("Evo[+ "&$H$3&"]"),_xlfn.AGGREGATE(15,6,(ROW(Evo[Evolution_Name])-MIN(ROW(Evo[Evolution_Name]))+1)/((INDIRECT("Evo[Max "&$H$3&"]")=$H9)*(INDIRECT("Evo[Max "&$H$3&"]")>0)),$G9)),"")} | K9: {=IFERROR(INDEX(INDIRECT("Evo[+ OVR]"),_xlfn.AGGREGATE(15,6,(ROW(Evo[Evolution_Name])-MIN(ROW(Evo[Evolution_Name]))+1)/((INDIRECT("Evo[Max "&$H$3&"]")=$H9)*(INDIRECT("Evo[Max "&$H$3&"]")>0)),$G9)),"")} | L9: {=IFERROR(INDEX(INDIRECT("Evo[Max OVR]"),_xlfn.AGGREGATE(15,6,(ROW(Evo[Evolution_Name])-MIN(ROW(Evo[Evolution_Name]))+1)/((INDIRECT("Evo[Max "&$H$3&"]")=$H9)*(INDIRECT("Evo[Max "&$H$3&"]")>0)),$G9)),"")} | M9: {=IFERROR(INDEX(INDIRECT("Evo[Req_Position]"),_xlfn.AGGREGATE(15,6,(ROW(Evo[Evolution_Name])-MIN(ROW(Evo[Evolution_Name]))+1)/((INDIRECT("Evo[Max "&$H$3&"]")=$H9)*(INDIRECT("Evo[Max "&$H$3&"]")>0)),$G9)),"")} | N9: {=IFERROR(INDEX(INDIRECT("Evo[Req_OVR_Max]"),_xlfn.AGGREGATE(15,6,(ROW(Evo[Evolution_Name])-MIN(ROW(Evo[Evolution_Name]))+1)/((INDIRECT("Evo[Max "&$H$3&"]")=$H9)*(INDIRECT("Evo[Max "&$H$3&"]")>0)),$G9)),"")} | O9: {=IFERROR(INDEX(INDIRECT("Evo[Req_Other]"),_xlfn.AGGREGATE(15,6,(ROW(Evo[Evolution_Name])-MIN(ROW(Evo[Evolution_Name]))+1)/((INDIRECT("Evo[Max "&$H$3&"]")=$H9)*(INDIRECT("Evo[Max "&$H$3&"]")>0)),$G9)),"")}
F10: 2위 | G10: 1 | H10: =_xlfn.MAXIFS(INDIRECT("Evo[Max "&$H$3&"]"),INDIRECT("Evo[Max "&$H$3&"]"),"<"&$H$5,INDIRECT("Evo[Max "&$H$3&"]"),">0") | I10: {=IFERROR(INDEX(Evo[Evolution_Name],_xlfn.AGGREGATE(15,6,(ROW(Evo[Evolution_Name])-MIN(ROW(Evo[Evolution_Name]))+1)/((INDIRECT("Evo[Max "&$H$3&"]")=$H10)*(INDIRECT("Evo[Max "&$H$3&"]")>0)),$G10)),"")} | J10: {=IFERROR(INDEX(INDIRECT("Evo[+ "&$H$3&"]"),_xlfn.AGGREGATE(15,6,(ROW(Evo[Evolution_Name])-MIN(ROW(Evo[Evolution_Name]))+1)/((INDIRECT("Evo[Max "&$H$3&"]")=$H10)*(INDIRECT("Evo[Max "&$H$3&"]")>0)),$G10)),"")} | K10: {=IFERROR(INDEX(INDIRECT("Evo[+ OVR]"),_xlfn.AGGREGATE(15,6,(ROW(Evo[Evolution_Name])-MIN(ROW(Evo[Evolution_Name]))+1)/((INDIRECT("Evo[Max "&$H$3&"]")=$H10)*(INDIRECT("Evo[Max "&$H$3&"]")>0)),$G10)),"")} | L10: {=IFERROR(INDEX(INDIRECT("Evo[Max OVR]"),_xlfn.AGGREGATE(15,6,(ROW(Evo[Evolution_Name])-MIN(ROW(Evo[Evolution_Name]))+1)/((INDIRECT("Evo[Max "&$H$3&"]")=$H10)*(INDIRECT("Evo[Max "&$H$3&"]")>0)),$G10)),"")} | M10: {=IFERROR(INDEX(INDIRECT("Evo[Req_Position]"),_xlfn.AGGREGATE(15,6,(ROW(Evo[Evolution_Name])-MIN(ROW(Evo[Evolution_Name]))+1)/((INDIRECT("Evo[Max "&$H$3&"]")=$H10)*(INDIRECT("Evo[Max "&$H$3&"]")>0)),$G10)),"")} | N10: {=IFERROR(INDEX(INDIRECT("Evo[Req_OVR_Max]"),_xlfn.AGGREGATE(15,6,(ROW(Evo[Evolution_Name])-MIN(ROW(Evo[Evolution_Name]))+1)/((INDIRECT("Evo[Max "&$H$3&"]")=$H10)*(INDIRECT("Evo[Max "&$H$3&"]")>0)),$G10)),"")} | O10: {=IFERROR(INDEX(INDIRECT("Evo[Req_Other]"),_xlfn.AGGREGATE(15,6,(ROW(Evo[Evolution_Name])-MIN(ROW(Evo[Evolution_Name]))+1)/((INDIRECT("Evo[Max "&$H$3&"]")=$H10)*(INDIRECT("Evo[Max "&$H$3&"]")>0)),$G10)),"")}
G11: 2 | H11: =_xlfn.MAXIFS(INDIRECT("Evo[Max "&$H$3&"]"),INDIRECT("Evo[Max "&$H$3&"]"),"<"&$H$5,INDIRECT("Evo[Max "&$H$3&"]"),">0") | I11: {=IFERROR(INDEX(Evo[Evolution_Name],_xlfn.AGGREGATE(15,6,(ROW(Evo[Evolution_Name])-MIN(ROW(Evo[Evolution_Name]))+1)/((INDIRECT("Evo[Max "&$H$3&"]")=$H11)*(INDIRECT("Evo[Max "&$H$3&"]")>0)),$G11)),"")} | J11: {=IFERROR(INDEX(INDIRECT("Evo[+ "&$H$3&"]"),_xlfn.AGGREGATE(15,6,(ROW(Evo[Evolution_Name])-MIN(ROW(Evo[Evolution_Name]))+1)/((INDIRECT("Evo[Max "&$H$3&"]")=$H11)*(INDIRECT("Evo[Max "&$H$3&"]")>0)),$G11)),"")} | K11: {=IFERROR(INDEX(INDIRECT("Evo[+ OVR]"),_xlfn.AGGREGATE(15,6,(ROW(Evo[Evolution_Name])-MIN(ROW(Evo[Evolution_Name]))+1)/((INDIRECT("Evo[Max "&$H$3&"]")=$H11)*(INDIRECT("Evo[Max "&$H$3&"]")>0)),$G11)),"")} | L11: {=IFERROR(INDEX(INDIRECT("Evo[Max OVR]"),_xlfn.AGGREGATE(15,6,(ROW(Evo[Evolution_Name])-MIN(ROW(Evo[Evolution_Name]))+1)/((INDIRECT("Evo[Max "&$H$3&"]")=$H11)*(INDIRECT("Evo[Max "&$H$3&"]")>0)),$G11)),"")} | M11: {=IFERROR(INDEX(INDIRECT("Evo[Req_Position]"),_xlfn.AGGREGATE(15,6,(ROW(Evo[Evolution_Name])-MIN(ROW(Evo[Evolution_Name]))+1)/((INDIRECT("Evo[Max "&$H$3&"]")=$H11)*(INDIRECT("Evo[Max "&$H$3&"]")>0)),$G11)),"")} | N11: {=IFERROR(INDEX(INDIRECT("Evo[Req_OVR_Max]"),_xlfn.AGGREGATE(15,6,(ROW(Evo[Evolution_Name])-MIN(ROW(Evo[Evolution_Name]))+1)/((INDIRECT("Evo[Max "&$H$3&"]")=$H11)*(INDIRECT("Evo[Max "&$H$3&"]")>0)),$G11)),"")} | O11: {=IFERROR(INDEX(INDIRECT("Evo[Req_Other]"),_xlfn.AGGREGATE(15,6,(ROW(Evo[Evolution_Name])-MIN(ROW(Evo[Evolution_Name]))+1)/((INDIRECT("Evo[Max "&$H$3&"]")=$H11)*(INDIRECT("Evo[Max "&$H$3&"]")>0)),$G11)),"")}
G12: 3 | H12: =_xlfn.MAXIFS(INDIRECT("Evo[Max "&$H$3&"]"),INDIRECT("Evo[Max "&$H$3&"]"),"<"&$H$5,INDIRECT("Evo[Max "&$H$3&"]"),">0") | I12: {=IFERROR(INDEX(Evo[Evolution_Name],_xlfn.AGGREGATE(15,6,(ROW(Evo[Evolution_Name])-MIN(ROW(Evo[Evolution_Name]))+1)/((INDIRECT("Evo[Max "&$H$3&"]")=$H12)*(INDIRECT("Evo[Max "&$H$3&"]")>0)),$G12)),"")} | J12: {=IFERROR(INDEX(INDIRECT("Evo[+ "&$H$3&"]"),_xlfn.AGGREGATE(15,6,(ROW(Evo[Evolution_Name])-MIN(ROW(Evo[Evolution_Name]))+1)/((INDIRECT("Evo[Max "&$H$3&"]")=$H12)*(INDIRECT("Evo[Max "&$H$3&"]")>0)),$G12)),"")} | K12: {=IFERROR(INDEX(INDIRECT("Evo[+ OVR]"),_xlfn.AGGREGATE(15,6,(ROW(Evo[Evolution_Name])-MIN(ROW(Evo[Evolution_Name]))+1)/((INDIRECT("Evo[Max "&$H$3&"]")=$H12)*(INDIRECT("Evo[Max "&$H$3&"]")>0)),$G12)),"")} | L12: {=IFERROR(INDEX(INDIRECT("Evo[Max OVR]"),_xlfn.AGGREGATE(15,6,(ROW(Evo[Evolution_Name])-MIN(ROW(Evo[Evolution_Name]))+1)/((INDIRECT("Evo[Max "&$H$3&"]")=$H12)*(INDIRECT("Evo[Max "&$H$3&"]")>0)),$G12)),"")} | M12: {=IFERROR(INDEX(INDIRECT("Evo[Req_Position]"),_xlfn.AGGREGATE(15,6,(ROW(Evo[Evolution_Name])-MIN(ROW(Evo[Evolution_Name]))+1)/((INDIRECT("Evo[Max "&$H$3&"]")=$H12)*(INDIRECT("Evo[Max "&$H$3&"]")>0)),$G12)),"")} | N12: {=IFERROR(INDEX(INDIRECT("Evo[Req_OVR_Max]"),_xlfn.AGGREGATE(15,6,(ROW(Evo[Evolution_Name])-MIN(ROW(Evo[Evolution_Name]))+1)/((INDIRECT("Evo[Max "&$H$3&"]")=$H12)*(INDIRECT("Evo[Max "&$H$3&"]")>0)),$G12)),"")} | O12: {=IFERROR(INDEX(INDIRECT("Evo[Req_Other]"),_xlfn.AGGREGATE(15,6,(ROW(Evo[Evolution_Name])-MIN(ROW(Evo[Evolution_Name]))+1)/((INDIRECT("Evo[Max "&$H$3&"]")=$H12)*(INDIRECT("Evo[Max "&$H$3&"]")>0)),$G12)),"")}
G13: 4 | H13: =_xlfn.MAXIFS(INDIRECT("Evo[Max "&$H$3&"]"),INDIRECT("Evo[Max "&$H$3&"]"),"<"&$H$5,INDIRECT("Evo[Max "&$H$3&"]"),">0") | I13: {=IFERROR(INDEX(Evo[Evolution_Name],_xlfn.AGGREGATE(15,6,(ROW(Evo[Evolution_Name])-MIN(ROW(Evo[Evolution_Name]))+1)/((INDIRECT("Evo[Max "&$H$3&"]")=$H13)*(INDIRECT("Evo[Max "&$H$3&"]")>0)),$G13)),"")} | J13: {=IFERROR(INDEX(INDIRECT("Evo[+ "&$H$3&"]"),_xlfn.AGGREGATE(15,6,(ROW(Evo[Evolution_Name])-MIN(ROW(Evo[Evolution_Name]))+1)/((INDIRECT("Evo[Max "&$H$3&"]")=$H13)*(INDIRECT("Evo[Max "&$H$3&"]")>0)),$G13)),"")} | K13: {=IFERROR(INDEX(INDIRECT("Evo[+ OVR]"),_xlfn.AGGREGATE(15,6,(ROW(Evo[Evolution_Name])-MIN(ROW(Evo[Evolution_Name]))+1)/((INDIRECT("Evo[Max "&$H$3&"]")=$H13)*(INDIRECT("Evo[Max "&$H$3&"]")>0)),$G13)),"")} | L13: {=IFERROR(INDEX(INDIRECT("Evo[Max OVR]"),_xlfn.AGGREGATE(15,6,(ROW(Evo[Evolution_Name])-MIN(ROW(Evo[Evolution_Name]))+1)/((INDIRECT("Evo[Max "&$H$3&"]")=$H13)*(INDIRECT("Evo[Max "&$H$3&"]")>0)),$G13)),"")} | M13: {=IFERROR(INDEX(INDIRECT("Evo[Req_Position]"),_xlfn.AGGREGATE(15,6,(ROW(Evo[Evolution_Name])-MIN(ROW(Evo[Evolution_Name]))+1)/((INDIRECT("Evo[Max "&$H$3&"]")=$H13)*(INDIRECT("Evo[Max "&$H$3&"]")>0)),$G13)),"")} | N13: {=IFERROR(INDEX(INDIRECT("Evo[Req_OVR_Max]"),_xlfn.AGGREGATE(15,6,(ROW(Evo[Evolution_Name])-MIN(ROW(Evo[Evolution_Name]))+1)/((INDIRECT("Evo[Max "&$H$3&"]")=$H13)*(INDIRECT("Evo[Max "&$H$3&"]")>0)),$G13)),"")} | O13: {=IFERROR(INDEX(INDIRECT("Evo[Req_Other]"),_xlfn.AGGREGATE(15,6,(ROW(Evo[Evolution_Name])-MIN(ROW(Evo[Evolution_Name]))+1)/((INDIRECT("Evo[Max "&$H$3&"]")=$H13)*(INDIRECT("Evo[Max "&$H$3&"]")>0)),$G13)),"")}
G14: 5 | H14: =_xlfn.MAXIFS(INDIRECT("Evo[Max "&$H$3&"]"),INDIRECT("Evo[Max "&$H$3&"]"),"<"&$H$5,INDIRECT("Evo[Max "&$H$3&"]"),">0") | I14: {=IFERROR(INDEX(Evo[Evolution_Name],_xlfn.AGGREGATE(15,6,(ROW(Evo[Evolution_Name])-MIN(ROW(Evo[Evolution_Name]))+1)/((INDIRECT("Evo[Max "&$H$3&"]")=$H14)*(INDIRECT("Evo[Max "&$H$3&"]")>0)),$G14)),"")} | J14: {=IFERROR(INDEX(INDIRECT("Evo[+ "&$H$3&"]"),_xlfn.AGGREGATE(15,6,(ROW(Evo[Evolution_Name])-MIN(ROW(Evo[Evolution_Name]))+1)/((INDIRECT("Evo[Max "&$H$3&"]")=$H14)*(INDIRECT("Evo[Max "&$H$3&"]")>0)),$G14)),"")} | K14: {=IFERROR(INDEX(INDIRECT("Evo[+ OVR]"),_xlfn.AGGREGATE(15,6,(ROW(Evo[Evolution_Name])-MIN(ROW(Evo[Evolution_Name]))+1)/((INDIRECT("Evo[Max "&$H$3&"]")=$H14)*(INDIRECT("Evo[Max "&$H$3&"]")>0)),$G14)),"")} | L14: {=IFERROR(INDEX(INDIRECT("Evo[Max OVR]"),_xlfn.AGGREGATE(15,6,(ROW(Evo[Evolution_Name])-MIN(ROW(Evo[Evolution_Name]))+1)/((INDIRECT("Evo[Max "&$H$3&"]")=$H14)*(INDIRECT("Evo[Max "&$H$3&"]")>0)),$G14)),"")} | M14: {=IFERROR(INDEX(INDIRECT("Evo[Req_Position]"),_xlfn.AGGREGATE(15,6,(ROW(Evo[Evolution_Name])-MIN(ROW(Evo[Evolution_Name]))+1)/((INDIRECT("Evo[Max "&$H$3&"]")=$H14)*(INDIRECT("Evo[Max "&$H$3&"]")>0)),$G14)),"")} | N14: {=IFERROR(INDEX(INDIRECT("Evo[Req_OVR_Max]"),_xlfn.AGGREGATE(15,6,(ROW(Evo[Evolution_Name])-MIN(ROW(Evo[Evolution_Name]))+1)/((INDIRECT("Evo[Max "&$H$3&"]")=$H14)*(INDIRECT("Evo[Max "&$H$3&"]")>0)),$G14)),"")} | O14: {=IFERROR(INDEX(INDIRECT("Evo[Req_Other]"),_xlfn.AGGREGATE(15,6,(ROW(Evo[Evolution_Name])-MIN(ROW(Evo[Evolution_Name]))+1)/((INDIRECT("Evo[Max "&$H$3&"]")=$H14)*(INDIRECT("Evo[Max "&$H$3&"]")>0)),$G14)),"")}
F15: 3위 | G15: 1 | H15: =_xlfn.MAXIFS(INDIRECT("Evo[Max "&$H$3&"]"),INDIRECT("Evo[Max "&$H$3&"]"),"<"&$H$10,INDIRECT("Evo[Max "&$H$3&"]"),">0") | I15: {=IFERROR(INDEX(Evo[Evolution_Name],_xlfn.AGGREGATE(15,6,(ROW(Evo[Evolution_Name])-MIN(ROW(Evo[Evolution_Name]))+1)/((INDIRECT("Evo[Max "&$H$3&"]")=$H15)*(INDIRECT("Evo[Max "&$H$3&"]")>0)),$G15)),"")} | J15: {=IFERROR(INDEX(INDIRECT("Evo[+ "&$H$3&"]"),_xlfn.AGGREGATE(15,6,(ROW(Evo[Evolution_Name])-MIN(ROW(Evo[Evolution_Name]))+1)/((INDIRECT("Evo[Max "&$H$3&"]")=$H15)*(INDIRECT("Evo[Max "&$H$3&"]")>0)),$G15)),"")} | K15: {=IFERROR(INDEX(INDIRECT("Evo[+ OVR]"),_xlfn.AGGREGATE(15,6,(ROW(Evo[Evolution_Name])-MIN(ROW(Evo[Evolution_Name]))+1)/((INDIRECT("Evo[Max "&$H$3&"]")=$H15)*(INDIRECT("Evo[Max "&$H$3&"]")>0)),$G15)),"")} | L15: {=IFERROR(INDEX(INDIRECT("Evo[Max OVR]"),_xlfn.AGGREGATE(15,6,(ROW(Evo[Evolution_Name])-MIN(ROW(Evo[Evolution_Name]))+1)/((INDIRECT("Evo[Max "&$H$3&"]")=$H15)*(INDIRECT("Evo[Max "&$H$3&"]")>0)),$G15)),"")} | M15: {=IFERROR(INDEX(INDIRECT("Evo[Req_Position]"),_xlfn.AGGREGATE(15,6,(ROW(Evo[Evolution_Name])-MIN(ROW(Evo[Evolution_Name]))+1)/((INDIRECT("Evo[Max "&$H$3&"]")=$H15)*(INDIRECT("Evo[Max "&$H$3&"]")>0)),$G15)),"")} | N15: {=IFERROR(INDEX(INDIRECT("Evo[Req_OVR_Max]"),_xlfn.AGGREGATE(15,6,(ROW(Evo[Evolution_Name])-MIN(ROW(Evo[Evolution_Name]))+1)/((INDIRECT("Evo[Max "&$H$3&"]")=$H15)*(INDIRECT("Evo[Max "&$H$3&"]")>0)),$G15)),"")} | O15: {=IFERROR(INDEX(INDIRECT("Evo[Req_Other]"),_xlfn.AGGREGATE(15,6,(ROW(Evo[Evolution_Name])-MIN(ROW(Evo[Evolution_Name]))+1)/((INDIRECT("Evo[Max "&$H$3&"]")=$H15)*(INDIRECT("Evo[Max "&$H$3&"]")>0)),$G15)),"")}
G16: 2 | H16: =_xlfn.MAXIFS(INDIRECT("Evo[Max "&$H$3&"]"),INDIRECT("Evo[Max "&$H$3&"]"),"<"&$H$10,INDIRECT("Evo[Max "&$H$3&"]"),">0") | I16: {=IFERROR(INDEX(Evo[Evolution_Name],_xlfn.AGGREGATE(15,6,(ROW(Evo[Evolution_Name])-MIN(ROW(Evo[Evolution_Name]))+1)/((INDIRECT("Evo[Max "&$H$3&"]")=$H16)*(INDIRECT("Evo[Max "&$H$3&"]")>0)),$G16)),"")} | J16: {=IFERROR(INDEX(INDIRECT("Evo[+ "&$H$3&"]"),_xlfn.AGGREGATE(15,6,(ROW(Evo[Evolution_Name])-MIN(ROW(Evo[Evolution_Name]))+1)/((INDIRECT("Evo[Max "&$H$3&"]")=$H16)*(INDIRECT("Evo[Max "&$H$3&"]")>0)),$G16)),"")} | K16: {=IFERROR(INDEX(INDIRECT("Evo[+ OVR]"),_xlfn.AGGREGATE(15,6,(ROW(Evo[Evolution_Name])-MIN(ROW(Evo[Evolution_Name]))+1)/((INDIRECT("Evo[Max "&$H$3&"]")=$H16)*(INDIRECT("Evo[Max "&$H$3&"]")>0)),$G16)),"")} | L16: {=IFERROR(INDEX(INDIRECT("Evo[Max OVR]"),_xlfn.AGGREGATE(15,6,(ROW(Evo[Evolution_Name])-MIN(ROW(Evo[Evolution_Name]))+1)/((INDIRECT("Evo[Max "&$H$3&"]")=$H16)*(INDIRECT("Evo[Max "&$H$3&"]")>0)),$G16)),"")} | M16: {=IFERROR(INDEX(INDIRECT("Evo[Req_Position]"),_xlfn.AGGREGATE(15,6,(ROW(Evo[Evolution_Name])-MIN(ROW(Evo[Evolution_Name]))+1)/((INDIRECT("Evo[Max "&$H$3&"]")=$H16)*(INDIRECT("Evo[Max "&$H$3&"]")>0)),$G16)),"")} | N16: {=IFERROR(INDEX(INDIRECT("Evo[Req_OVR_Max]"),_xlfn.AGGREGATE(15,6,(ROW(Evo[Evolution_Name])-MIN(ROW(Evo[Evolution_Name]))+1)/((INDIRECT("Evo[Max "&$H$3&"]")=$H16)*(INDIRECT("Evo[Max "&$H$3&"]")>0)),$G16)),"")} | O16: {=IFERROR(INDEX(INDIRECT("Evo[Req_Other]"),_xlfn.AGGREGATE(15,6,(ROW(Evo[Evolution_Name])-MIN(ROW(Evo[Evolution_Name]))+1)/((INDIRECT("Evo[Max "&$H$3&"]")=$H16)*(INDIRECT("Evo[Max "&$H$3&"]")>0)),$G16)),"")}
G17: 3 | H17: =_xlfn.MAXIFS(INDIRECT("Evo[Max "&$H$3&"]"),INDIRECT("Evo[Max "&$H$3&"]"),"<"&$H$10,INDIRECT("Evo[Max "&$H$3&"]"),">0") | I17: {=IFERROR(INDEX(Evo[Evolution_Name],_xlfn.AGGREGATE(15,6,(ROW(Evo[Evolution_Name])-MIN(ROW(Evo[Evolution_Name]))+1)/((INDIRECT("Evo[Max "&$H$3&"]")=$H17)*(INDIRECT("Evo[Max "&$H$3&"]")>0)),$G17)),"")} | J17: {=IFERROR(INDEX(INDIRECT("Evo[+ "&$H$3&"]"),_xlfn.AGGREGATE(15,6,(ROW(Evo[Evolution_Name])-MIN(ROW(Evo[Evolution_Name]))+1)/((INDIRECT("Evo[Max "&$H$3&"]")=$H17)*(INDIRECT("Evo[Max "&$H$3&"]")>0)),$G17)),"")} | K17: {=IFERROR(INDEX(INDIRECT("Evo[+ OVR]"),_xlfn.AGGREGATE(15,6,(ROW(Evo[Evolution_Name])-MIN(ROW(Evo[Evolution_Name]))+1)/((INDIRECT("Evo[Max "&$H$3&"]")=$H17)*(INDIRECT("Evo[Max "&$H$3&"]")>0)),$G17)),"")} | L17: {=IFERROR(INDEX(INDIRECT("Evo[Max OVR]"),_xlfn.AGGREGATE(15,6,(ROW(Evo[Evolution_Name])-MIN(ROW(Evo[Evolution_Name]))+1)/((INDIRECT("Evo[Max "&$H$3&"]")=$H17)*(INDIRECT("Evo[Max "&$H$3&"]")>0)),$G17)),"")} | M17: {=IFERROR(INDEX(INDIRECT("Evo[Req_Position]"),_xlfn.AGGREGATE(15,6,(ROW(Evo[Evolution_Name])-MIN(ROW(Evo[Evolution_Name]))+1)/((INDIRECT("Evo[Max "&$H$3&"]")=$H17)*(INDIRECT("Evo[Max "&$H$3&"]")>0)),$G17)),"")} | N17: {=IFERROR(INDEX(INDIRECT("Evo[Req_OVR_Max]"),_xlfn.AGGREGATE(15,6,(ROW(Evo[Evolution_Name])-MIN(ROW(Evo[Evolution_Name]))+1)/((INDIRECT("Evo[Max "&$H$3&"]")=$H17)*(INDIRECT("Evo[Max "&$H$3&"]")>0)),$G17)),"")} | O17: {=IFERROR(INDEX(INDIRECT("Evo[Req_Other]"),_xlfn.AGGREGATE(15,6,(ROW(Evo[Evolution_Name])-MIN(ROW(Evo[Evolution_Name]))+1)/((INDIRECT("Evo[Max "&$H$3&"]")=$H17)*(INDIRECT("Evo[Max "&$H$3&"]")>0)),$G17)),"")}
G18: 4 | H18: =_xlfn.MAXIFS(INDIRECT("Evo[Max "&$H$3&"]"),INDIRECT("Evo[Max "&$H$3&"]"),"<"&$H$10,INDIRECT("Evo[Max "&$H$3&"]"),">0") | I18: {=IFERROR(INDEX(Evo[Evolution_Name],_xlfn.AGGREGATE(15,6,(ROW(Evo[Evolution_Name])-MIN(ROW(Evo[Evolution_Name]))+1)/((INDIRECT("Evo[Max "&$H$3&"]")=$H18)*(INDIRECT("Evo[Max "&$H$3&"]")>0)),$G18)),"")} | J18: {=IFERROR(INDEX(INDIRECT("Evo[+ "&$H$3&"]"),_xlfn.AGGREGATE(15,6,(ROW(Evo[Evolution_Name])-MIN(ROW(Evo[Evolution_Name]))+1)/((INDIRECT("Evo[Max "&$H$3&"]")=$H18)*(INDIRECT("Evo[Max "&$H$3&"]")>0)),$G18)),"")} | K18: {=IFERROR(INDEX(INDIRECT("Evo[+ OVR]"),_xlfn.AGGREGATE(15,6,(ROW(Evo[Evolution_Name])-MIN(ROW(Evo[Evolution_Name]))+1)/((INDIRECT("Evo[Max "&$H$3&"]")=$H18)*(INDIRECT("Evo[Max "&$H$3&"]")>0)),$G18)),"")} | L18: {=IFERROR(INDEX(INDIRECT("Evo[Max OVR]"),_xlfn.AGGREGATE(15,6,(ROW(Evo[Evolution_Name])-MIN(ROW(Evo[Evolution_Name]))+1)/((INDIRECT("Evo[Max "&$H$3&"]")=$H18)*(INDIRECT("Evo[Max "&$H$3&"]")>0)),$G18)),"")} | M18: {=IFERROR(INDEX(INDIRECT("Evo[Req_Position]"),_xlfn.AGGREGATE(15,6,(ROW(Evo[Evolution_Name])-MIN(ROW(Evo[Evolution_Name]))+1)/((INDIRECT("Evo[Max "&$H$3&"]")=$H18)*(INDIRECT("Evo[Max "&$H$3&"]")>0)),$G18)),"")} | N18: {=IFERROR(INDEX(INDIRECT("Evo[Req_OVR_Max]"),_xlfn.AGGREGATE(15,6,(ROW(Evo[Evolution_Name])-MIN(ROW(Evo[Evolution_Name]))+1)/((INDIRECT("Evo[Max "&$H$3&"]")=$H18)*(INDIRECT("Evo[Max "&$H$3&"]")>0)),$G18)),"")} | O18: {=IFERROR(INDEX(INDIRECT("Evo[Req_Other]"),_xlfn.AGGREGATE(15,6,(ROW(Evo[Evolution_Name])-MIN(ROW(Evo[Evolution_Name]))+1)/((INDIRECT("Evo[Max "&$H$3&"]")=$H18)*(INDIRECT("Evo[Max "&$H$3&"]")>0)),$G18)),"")}
G19: 5 | H19: =_xlfn.MAXIFS(INDIRECT("Evo[Max "&$H$3&"]"),INDIRECT("Evo[Max "&$H$3&"]"),"<"&$H$10,INDIRECT("Evo[Max "&$H$3&"]"),">0") | I19: {=IFERROR(INDEX(Evo[Evolution_Name],_xlfn.AGGREGATE(15,6,(ROW(Evo[Evolution_Name])-MIN(ROW(Evo[Evolution_Name]))+1)/((INDIRECT("Evo[Max "&$H$3&"]")=$H19)*(INDIRECT("Evo[Max "&$H$3&"]")>0)),$G19)),"")} | J19: {=IFERROR(INDEX(INDIRECT("Evo[+ "&$H$3&"]"),_xlfn.AGGREGATE(15,6,(ROW(Evo[Evolution_Name])-MIN(ROW(Evo[Evolution_Name]))+1)/((INDIRECT("Evo[Max "&$H$3&"]")=$H19)*(INDIRECT("Evo[Max "&$H$3&"]")>0)),$G19)),"")} | K19: {=IFERROR(INDEX(INDIRECT("Evo[+ OVR]"),_xlfn.AGGREGATE(15,6,(ROW(Evo[Evolution_Name])-MIN(ROW(Evo[Evolution_Name]))+1)/((INDIRECT("Evo[Max "&$H$3&"]")=$H19)*(INDIRECT("Evo[Max "&$H$3&"]")>0)),$G19)),"")} | L19: {=IFERROR(INDEX(INDIRECT("Evo[Max OVR]"),_xlfn.AGGREGATE(15,6,(ROW(Evo[Evolution_Name])-MIN(ROW(Evo[Evolution_Name]))+1)/((INDIRECT("Evo[Max "&$H$3&"]")=$H19)*(INDIRECT("Evo[Max "&$H$3&"]")>0)),$G19)),"")} | M19: {=IFERROR(INDEX(INDIRECT("Evo[Req_Position]"),_xlfn.AGGREGATE(15,6,(ROW(Evo[Evolution_Name])-MIN(ROW(Evo[Evolution_Name]))+1)/((INDIRECT("Evo[Max "&$H$3&"]")=$H19)*(INDIRECT("Evo[Max "&$H$3&"]")>0)),$G19)),"")} | N19: {=IFERROR(INDEX(INDIRECT("Evo[Req_OVR_Max]"),_xlfn.AGGREGATE(15,6,(ROW(Evo[Evolution_Name])-MIN(ROW(Evo[Evolution_Name]))+1)/((INDIRECT("Evo[Max "&$H$3&"]")=$H19)*(INDIRECT("Evo[Max "&$H$3&"]")>0)),$G19)),"")} | O19: {=IFERROR(INDEX(INDIRECT("Evo[Req_Other]"),_xlfn.AGGREGATE(15,6,(ROW(Evo[Evolution_Name])-MIN(ROW(Evo[Evolution_Name]))+1)/((INDIRECT("Evo[Max "&$H$3&"]")=$H19)*(INDIRECT("Evo[Max "&$H$3&"]")>0)),$G19)),"")}
F20: 4위 | G20: 1 | H20: =_xlfn.MAXIFS(INDIRECT("Evo[Max "&$H$3&"]"),INDIRECT("Evo[Max "&$H$3&"]"),"<"&$H$15,INDIRECT("Evo[Max "&$H$3&"]"),">0") | I20: {=IFERROR(INDEX(Evo[Evolution_Name],_xlfn.AGGREGATE(15,6,(ROW(Evo[Evolution_Name])-MIN(ROW(Evo[Evolution_Name]))+1)/((INDIRECT("Evo[Max "&$H$3&"]")=$H20)*(INDIRECT("Evo[Max "&$H$3&"]")>0)),$G20)),"")} | J20: {=IFERROR(INDEX(INDIRECT("Evo[+ "&$H$3&"]"),_xlfn.AGGREGATE(15,6,(ROW(Evo[Evolution_Name])-MIN(ROW(Evo[Evolution_Name]))+1)/((INDIRECT("Evo[Max "&$H$3&"]")=$H20)*(INDIRECT("Evo[Max "&$H$3&"]")>0)),$G20)),"")} | K20: {=IFERROR(INDEX(INDIRECT("Evo[+ OVR]"),_xlfn.AGGREGATE(15,6,(ROW(Evo[Evolution_Name])-MIN(ROW(Evo[Evolution_Name]))+1)/((INDIRECT("Evo[Max "&$H$3&"]")=$H20)*(INDIRECT("Evo[Max "&$H$3&"]")>0)),$G20)),"")} | L20: {=IFERROR(INDEX(INDIRECT("Evo[Max OVR]"),_xlfn.AGGREGATE(15,6,(ROW(Evo[Evolution_Name])-MIN(ROW(Evo[Evolution_Name]))+1)/((INDIRECT("Evo[Max "&$H$3&"]")=$H20)*(INDIRECT("Evo[Max "&$H$3&"]")>0)),$G20)),"")} | M20: {=IFERROR(INDEX(INDIRECT("Evo[Req_Position]"),_xlfn.AGGREGATE(15,6,(ROW(Evo[Evolution_Name])-MIN(ROW(Evo[Evolution_Name]))+1)/((INDIRECT("Evo[Max "&$H$3&"]")=$H20)*(INDIRECT("Evo[Max "&$H$3&"]")>0)),$G20)),"")} | N20: {=IFERROR(INDEX(INDIRECT("Evo[Req_OVR_Max]"),_xlfn.AGGREGATE(15,6,(ROW(Evo[Evolution_Name])-MIN(ROW(Evo[Evolution_Name]))+1)/((INDIRECT("Evo[Max "&$H$3&"]")=$H20)*(INDIRECT("Evo[Max "&$H$3&"]")>0)),$G20)),"")} | O20: {=IFERROR(INDEX(INDIRECT("Evo[Req_Other]"),_xlfn.AGGREGATE(15,6,(ROW(Evo[Evolution_Name])-MIN(ROW(Evo[Evolution_Name]))+1)/((INDIRECT("Evo[Max "&$H$3&"]")=$H20)*(INDIRECT("Evo[Max "&$H$3&"]")>0)),$G20)),"")}
G21: 2 | H21: =_xlfn.MAXIFS(INDIRECT("Evo[Max "&$H$3&"]"),INDIRECT("Evo[Max "&$H$3&"]"),"<"&$H$15,INDIRECT("Evo[Max "&$H$3&"]"),">0") | I21: {=IFERROR(INDEX(Evo[Evolution_Name],_xlfn.AGGREGATE(15,6,(ROW(Evo[Evolution_Name])-MIN(ROW(Evo[Evolution_Name]))+1)/((INDIRECT("Evo[Max "&$H$3&"]")=$H21)*(INDIRECT("Evo[Max "&$H$3&"]")>0)),$G21)),"")} | J21: {=IFERROR(INDEX(INDIRECT("Evo[+ "&$H$3&"]"),_xlfn.AGGREGATE(15,6,(ROW(Evo[Evolution_Name])-MIN(ROW(Evo[Evolution_Name]))+1)/((INDIRECT("Evo[Max "&$H$3&"]")=$H21)*(INDIRECT("Evo[Max "&$H$3&"]")>0)),$G21)),"")} | K21: {=IFERROR(INDEX(INDIRECT("Evo[+ OVR]"),_xlfn.AGGREGATE(15,6,(ROW(Evo[Evolution_Name])-MIN(ROW(Evo[Evolution_Name]))+1)/((INDIRECT("Evo[Max "&$H$3&"]")=$H21)*(INDIRECT("Evo[Max "&$H$3&"]")>0)),$G21)),"")} | L21: {=IFERROR(INDEX(INDIRECT("Evo[Max OVR]"),_xlfn.AGGREGATE(15,6,(ROW(Evo[Evolution_Name])-MIN(ROW(Evo[Evolution_Name]))+1)/((INDIRECT("Evo[Max "&$H$3&"]")=$H21)*(INDIRECT("Evo[Max "&$H$3&"]")>0)),$G21)),"")} | M21: {=IFERROR(INDEX(INDIRECT("Evo[Req_Position]"),_xlfn.AGGREGATE(15,6,(ROW(Evo[Evolution_Name])-MIN(ROW(Evo[Evolution_Name]))+1)/((INDIRECT("Evo[Max "&$H$3&"]")=$H21)*(INDIRECT("Evo[Max "&$H$3&"]")>0)),$G21)),"")} | N21: {=IFERROR(INDEX(INDIRECT("Evo[Req_OVR_Max]"),_xlfn.AGGREGATE(15,6,(ROW(Evo[Evolution_Name])-MIN(ROW(Evo[Evolution_Name]))+1)/((INDIRECT("Evo[Max "&$H$3&"]")=$H21)*(INDIRECT("Evo[Max "&$H$3&"]")>0)),$G21)),"")} | O21: {=IFERROR(INDEX(INDIRECT("Evo[Req_Other]"),_xlfn.AGGREGATE(15,6,(ROW(Evo[Evolution_Name])-MIN(ROW(Evo[Evolution_Name]))+1)/((INDIRECT("Evo[Max "&$H$3&"]")=$H21)*(INDIRECT("Evo[Max "&$H$3&"]")>0)),$G21)),"")}
G22: 3 | H22: =_xlfn.MAXIFS(INDIRECT("Evo[Max "&$H$3&"]"),INDIRECT("Evo[Max "&$H$3&"]"),"<"&$H$15,INDIRECT("Evo[Max "&$H$3&"]"),">0") | I22: {=IFERROR(INDEX(Evo[Evolution_Name],_xlfn.AGGREGATE(15,6,(ROW(Evo[Evolution_Name])-MIN(ROW(Evo[Evolution_Name]))+1)/((INDIRECT("Evo[Max "&$H$3&"]")=$H22)*(INDIRECT("Evo[Max "&$H$3&"]")>0)),$G22)),"")} | J22: {=IFERROR(INDEX(INDIRECT("Evo[+ "&$H$3&"]"),_xlfn.AGGREGATE(15,6,(ROW(Evo[Evolution_Name])-MIN(ROW(Evo[Evolution_Name]))+1)/((INDIRECT("Evo[Max "&$H$3&"]")=$H22)*(INDIRECT("Evo[Max "&$H$3&"]")>0)),$G22)),"")} | K22: {=IFERROR(INDEX(INDIRECT("Evo[+ OVR]"),_xlfn.AGGREGATE(15,6,(ROW(Evo[Evolution_Name])-MIN(ROW(Evo[Evolution_Name]))+1)/((INDIRECT("Evo[Max "&$H$3&"]")=$H22)*(INDIRECT("Evo[Max "&$H$3&"]")>0)),$G22)),"")} | L22: {=IFERROR(INDEX(INDIRECT("Evo[Max OVR]"),_xlfn.AGGREGATE(15,6,(ROW(Evo[Evolution_Name])-MIN(ROW(Evo[Evolution_Name]))+1)/((INDIRECT("Evo[Max "&$H$3&"]")=$H22)*(INDIRECT("Evo[Max "&$H$3&"]")>0)),$G22)),"")} | M22: {=IFERROR(INDEX(INDIRECT("Evo[Req_Position]"),_xlfn.AGGREGATE(15,6,(ROW(Evo[Evolution_Name])-MIN(ROW(Evo[Evolution_Name]))+1)/((INDIRECT("Evo[Max "&$H$3&"]")=$H22)*(INDIRECT("Evo[Max "&$H$3&"]")>0)),$G22)),"")} | N22: {=IFERROR(INDEX(INDIRECT("Evo[Req_OVR_Max]"),_xlfn.AGGREGATE(15,6,(ROW(Evo[Evolution_Name])-MIN(ROW(Evo[Evolution_Name]))+1)/((INDIRECT("Evo[Max "&$H$3&"]")=$H22)*(INDIRECT("Evo[Max "&$H$3&"]")>0)),$G22)),"")} | O22: {=IFERROR(INDEX(INDIRECT("Evo[Req_Other]"),_xlfn.AGGREGATE(15,6,(ROW(Evo[Evolution_Name])-MIN(ROW(Evo[Evolution_Name]))+1)/((INDIRECT("Evo[Max "&$H$3&"]")=$H22)*(INDIRECT("Evo[Max "&$H$3&"]")>0)),$G22)),"")}
G23: 4 | H23: =_xlfn.MAXIFS(INDIRECT("Evo[Max "&$H$3&"]"),INDIRECT("Evo[Max "&$H$3&"]"),"<"&$H$15,INDIRECT("Evo[Max "&$H$3&"]"),">0") | I23: {=IFERROR(INDEX(Evo[Evolution_Name],_xlfn.AGGREGATE(15,6,(ROW(Evo[Evolution_Name])-MIN(ROW(Evo[Evolution_Name]))+1)/((INDIRECT("Evo[Max "&$H$3&"]")=$H23)*(INDIRECT("Evo[Max "&$H$3&"]")>0)),$G23)),"")} | J23: {=IFERROR(INDEX(INDIRECT("Evo[+ "&$H$3&"]"),_xlfn.AGGREGATE(15,6,(ROW(Evo[Evolution_Name])-MIN(ROW(Evo[Evolution_Name]))+1)/((INDIRECT("Evo[Max "&$H$3&"]")=$H23)*(INDIRECT("Evo[Max "&$H$3&"]")>0)),$G23)),"")} | K23: {=IFERROR(INDEX(INDIRECT("Evo[+ OVR]"),_xlfn.AGGREGATE(15,6,(ROW(Evo[Evolution_Name])-MIN(ROW(Evo[Evolution_Name]))+1)/((INDIRECT("Evo[Max "&$H$3&"]")=$H23)*(INDIRECT("Evo[Max "&$H$3&"]")>0)),$G23)),"")} | L23: {=IFERROR(INDEX(INDIRECT("Evo[Max OVR]"),_xlfn.AGGREGATE(15,6,(ROW(Evo[Evolution_Name])-MIN(ROW(Evo[Evolution_Name]))+1)/((INDIRECT("Evo[Max "&$H$3&"]")=$H23)*(INDIRECT("Evo[Max "&$H$3&"]")>0)),$G23)),"")} | M23: {=IFERROR(INDEX(INDIRECT("Evo[Req_Position]"),_xlfn.AGGREGATE(15,6,(ROW(Evo[Evolution_Name])-MIN(ROW(Evo[Evolution_Name]))+1)/((INDIRECT("Evo[Max "&$H$3&"]")=$H23)*(INDIRECT("Evo[Max "&$H$3&"]")>0)),$G23)),"")} | N23: {=IFERROR(INDEX(INDIRECT("Evo[Req_OVR_Max]"),_xlfn.AGGREGATE(15,6,(ROW(Evo[Evolution_Name])-MIN(ROW(Evo[Evolution_Name]))+1)/((INDIRECT("Evo[Max "&$H$3&"]")=$H23)*(INDIRECT("Evo[Max "&$H$3&"]")>0)),$G23)),"")} | O23: {=IFERROR(INDEX(INDIRECT("Evo[Req_Other]"),_xlfn.AGGREGATE(15,6,(ROW(Evo[Evolution_Name])-MIN(ROW(Evo[Evolution_Name]))+1)/((INDIRECT("Evo[Max "&$H$3&"]")=$H23)*(INDIRECT("Evo[Max "&$H$3&"]")>0)),$G23)),"")}
G24: 5 | H24: =_xlfn.MAXIFS(INDIRECT("Evo[Max "&$H$3&"]"),INDIRECT("Evo[Max "&$H$3&"]"),"<"&$H$15,INDIRECT("Evo[Max "&$H$3&"]"),">0") | I24: {=IFERROR(INDEX(Evo[Evolution_Name],_xlfn.AGGREGATE(15,6,(ROW(Evo[Evolution_Name])-MIN(ROW(Evo[Evolution_Name]))+1)/((INDIRECT("Evo[Max "&$H$3&"]")=$H24)*(INDIRECT("Evo[Max "&$H$3&"]")>0)),$G24)),"")} | J24: {=IFERROR(INDEX(INDIRECT("Evo[+ "&$H$3&"]"),_xlfn.AGGREGATE(15,6,(ROW(Evo[Evolution_Name])-MIN(ROW(Evo[Evolution_Name]))+1)/((INDIRECT("Evo[Max "&$H$3&"]")=$H24)*(INDIRECT("Evo[Max "&$H$3&"]")>0)),$G24)),"")} | K24: {=IFERROR(INDEX(INDIRECT("Evo[+ OVR]"),_xlfn.AGGREGATE(15,6,(ROW(Evo[Evolution_Name])-MIN(ROW(Evo[Evolution_Name]))+1)/((INDIRECT("Evo[Max "&$H$3&"]")=$H24)*(INDIRECT("Evo[Max "&$H$3&"]")>0)),$G24)),"")} | L24: {=IFERROR(INDEX(INDIRECT("Evo[Max OVR]"),_xlfn.AGGREGATE(15,6,(ROW(Evo[Evolution_Name])-MIN(ROW(Evo[Evolution_Name]))+1)/((INDIRECT("Evo[Max "&$H$3&"]")=$H24)*(INDIRECT("Evo[Max "&$H$3&"]")>0)),$G24)),"")} | M24: {=IFERROR(INDEX(INDIRECT("Evo[Req_Position]"),_xlfn.AGGREGATE(15,6,(ROW(Evo[Evolution_Name])-MIN(ROW(Evo[Evolution_Name]))+1)/((INDIRECT("Evo[Max "&$H$3&"]")=$H24)*(INDIRECT("Evo[Max "&$H$3&"]")>0)),$G24)),"")} | N24: {=IFERROR(INDEX(INDIRECT("Evo[Req_OVR_Max]"),_xlfn.AGGREGATE(15,6,(ROW(Evo[Evolution_Name])-MIN(ROW(Evo[Evolution_Name]))+1)/((INDIRECT("Evo[Max "&$H$3&"]")=$H24)*(INDIRECT("Evo[Max "&$H$3&"]")>0)),$G24)),"")} | O24: {=IFERROR(INDEX(INDIRECT("Evo[Req_Other]"),_xlfn.AGGREGATE(15,6,(ROW(Evo[Evolution_Name])-MIN(ROW(Evo[Evolution_Name]))+1)/((INDIRECT("Evo[Max "&$H$3&"]")=$H24)*(INDIRECT("Evo[Max "&$H$3&"]")>0)),$G24)),"")}
F25: 5위 | G25: 1 | H25: =_xlfn.MAXIFS(INDIRECT("Evo[Max "&$H$3&"]"),INDIRECT("Evo[Max "&$H$3&"]"),"<"&$H$20,INDIRECT("Evo[Max "&$H$3&"]"),">0") | I25: {=IFERROR(INDEX(Evo[Evolution_Name],_xlfn.AGGREGATE(15,6,(ROW(Evo[Evolution_Name])-MIN(ROW(Evo[Evolution_Name]))+1)/((INDIRECT("Evo[Max "&$H$3&"]")=$H25)*(INDIRECT("Evo[Max "&$H$3&"]")>0)),$G25)),"")} | J25: {=IFERROR(INDEX(INDIRECT("Evo[+ "&$H$3&"]"),_xlfn.AGGREGATE(15,6,(ROW(Evo[Evolution_Name])-MIN(ROW(Evo[Evolution_Name]))+1)/((INDIRECT("Evo[Max "&$H$3&"]")=$H25)*(INDIRECT("Evo[Max "&$H$3&"]")>0)),$G25)),"")} | K25: {=IFERROR(INDEX(INDIRECT("Evo[+ OVR]"),_xlfn.AGGREGATE(15,6,(ROW(Evo[Evolution_Name])-MIN(ROW(Evo[Evolution_Name]))+1)/((INDIRECT("Evo[Max "&$H$3&"]")=$H25)*(INDIRECT("Evo[Max "&$H$3&"]")>0)),$G25)),"")} | L25: {=IFERROR(INDEX(INDIRECT("Evo[Max OVR]"),_xlfn.AGGREGATE(15,6,(ROW(Evo[Evolution_Name])-MIN(ROW(Evo[Evolution_Name]))+1)/((INDIRECT("Evo[Max "&$H$3&"]")=$H25)*(INDIRECT("Evo[Max "&$H$3&"]")>0)),$G25)),"")} | M25: {=IFERROR(INDEX(INDIRECT("Evo[Req_Position]"),_xlfn.AGGREGATE(15,6,(ROW(Evo[Evolution_Name])-MIN(ROW(Evo[Evolution_Name]))+1)/((INDIRECT("Evo[Max "&$H$3&"]")=$H25)*(INDIRECT("Evo[Max "&$H$3&"]")>0)),$G25)),"")} | N25: {=IFERROR(INDEX(INDIRECT("Evo[Req_OVR_Max]"),_xlfn.AGGREGATE(15,6,(ROW(Evo[Evolution_Name])-MIN(ROW(Evo[Evolution_Name]))+1)/((INDIRECT("Evo[Max "&$H$3&"]")=$H25)*(INDIRECT("Evo[Max "&$H$3&"]")>0)),$G25)),"")} | O25: {=IFERROR(INDEX(INDIRECT("Evo[Req_Other]"),_xlfn.AGGREGATE(15,6,(ROW(Evo[Evolution_Name])-MIN(ROW(Evo[Evolution_Name]))+1)/((INDIRECT("Evo[Max "&$H$3&"]")=$H25)*(INDIRECT("Evo[Max "&$H$3&"]")>0)),$G25)),"")}
G26: 2 | H26: =_xlfn.MAXIFS(INDIRECT("Evo[Max "&$H$3&"]"),INDIRECT("Evo[Max "&$H$3&"]"),"<"&$H$20,INDIRECT("Evo[Max "&$H$3&"]"),">0") | I26: {=IFERROR(INDEX(Evo[Evolution_Name],_xlfn.AGGREGATE(15,6,(ROW(Evo[Evolution_Name])-MIN(ROW(Evo[Evolution_Name]))+1)/((INDIRECT("Evo[Max "&$H$3&"]")=$H26)*(INDIRECT("Evo[Max "&$H$3&"]")>0)),$G26)),"")} | J26: {=IFERROR(INDEX(INDIRECT("Evo[+ "&$H$3&"]"),_xlfn.AGGREGATE(15,6,(ROW(Evo[Evolution_Name])-MIN(ROW(Evo[Evolution_Name]))+1)/((INDIRECT("Evo[Max "&$H$3&"]")=$H26)*(INDIRECT("Evo[Max "&$H$3&"]")>0)),$G26)),"")} | K26: {=IFERROR(INDEX(INDIRECT("Evo[+ OVR]"),_xlfn.AGGREGATE(15,6,(ROW(Evo[Evolution_Name])-MIN(ROW(Evo[Evolution_Name]))+1)/((INDIRECT("Evo[Max "&$H$3&"]")=$H26)*(INDIRECT("Evo[Max "&$H$3&"]")>0)),$G26)),"")} | L26: {=IFERROR(INDEX(INDIRECT("Evo[Max OVR]"),_xlfn.AGGREGATE(15,6,(ROW(Evo[Evolution_Name])-MIN(ROW(Evo[Evolution_Name]))+1)/((INDIRECT("Evo[Max "&$H$3&"]")=$H26)*(INDIRECT("Evo[Max "&$H$3&"]")>0)),$G26)),"")} | M26: {=IFERROR(INDEX(INDIRECT("Evo[Req_Position]"),_xlfn.AGGREGATE(15,6,(ROW(Evo[Evolution_Name])-MIN(ROW(Evo[Evolution_Name]))+1)/((INDIRECT("Evo[Max "&$H$3&"]")=$H26)*(INDIRECT("Evo[Max "&$H$3&"]")>0)),$G26)),"")} | N26: {=IFERROR(INDEX(INDIRECT("Evo[Req_OVR_Max]"),_xlfn.AGGREGATE(15,6,(ROW(Evo[Evolution_Name])-MIN(ROW(Evo[Evolution_Name]))+1)/((INDIRECT("Evo[Max "&$H$3&"]")=$H26)*(INDIRECT("Evo[Max "&$H$3&"]")>0)),$G26)),"")} | O26: {=IFERROR(INDEX(INDIRECT("Evo[Req_Other]"),_xlfn.AGGREGATE(15,6,(ROW(Evo[Evolution_Name])-MIN(ROW(Evo[Evolution_Name]))+1)/((INDIRECT("Evo[Max "&$H$3&"]")=$H26)*(INDIRECT("Evo[Max "&$H$3&"]")>0)),$G26)),"")}
G27: 3 | H27: =_xlfn.MAXIFS(INDIRECT("Evo[Max "&$H$3&"]"),INDIRECT("Evo[Max "&$H$3&"]"),"<"&$H$20,INDIRECT("Evo[Max "&$H$3&"]"),">0") | I27: {=IFERROR(INDEX(Evo[Evolution_Name],_xlfn.AGGREGATE(15,6,(ROW(Evo[Evolution_Name])-MIN(ROW(Evo[Evolution_Name]))+1)/((INDIRECT("Evo[Max "&$H$3&"]")=$H27)*(INDIRECT("Evo[Max "&$H$3&"]")>0)),$G27)),"")} | J27: {=IFERROR(INDEX(INDIRECT("Evo[+ "&$H$3&"]"),_xlfn.AGGREGATE(15,6,(ROW(Evo[Evolution_Name])-MIN(ROW(Evo[Evolution_Name]))+1)/((INDIRECT("Evo[Max "&$H$3&"]")=$H27)*(INDIRECT("Evo[Max "&$H$3&"]")>0)),$G27)),"")} | K27: {=IFERROR(INDEX(INDIRECT("Evo[+ OVR]"),_xlfn.AGGREGATE(15,6,(ROW(Evo[Evolution_Name])-MIN(ROW(Evo[Evolution_Name]))+1)/((INDIRECT("Evo[Max "&$H$3&"]")=$H27)*(INDIRECT("Evo[Max "&$H$3&"]")>0)),$G27)),"")} | L27: {=IFERROR(INDEX(INDIRECT("Evo[Max OVR]"),_xlfn.AGGREGATE(15,6,(ROW(Evo[Evolution_Name])-MIN(ROW(Evo[Evolution_Name]))+1)/((INDIRECT("Evo[Max "&$H$3&"]")=$H27)*(INDIRECT("Evo[Max "&$H$3&"]")>0)),$G27)),"")} | M27: {=IFERROR(INDEX(INDIRECT("Evo[Req_Position]"),_xlfn.AGGREGATE(15,6,(ROW(Evo[Evolution_Name])-MIN(ROW(Evo[Evolution_Name]))+1)/((INDIRECT("Evo[Max "&$H$3&"]")=$H27)*(INDIRECT("Evo[Max "&$H$3&"]")>0)),$G27)),"")} | N27: {=IFERROR(INDEX(INDIRECT("Evo[Req_OVR_Max]"),_xlfn.AGGREGATE(15,6,(ROW(Evo[Evolution_Name])-MIN(ROW(Evo[Evolution_Name]))+1)/((INDIRECT("Evo[Max "&$H$3&"]")=$H27)*(INDIRECT("Evo[Max "&$H$3&"]")>0)),$G27)),"")} | O27: {=IFERROR(INDEX(INDIRECT("Evo[Req_Other]"),_xlfn.AGGREGATE(15,6,(ROW(Evo[Evolution_Name])-MIN(ROW(Evo[Evolution_Name]))+1)/((INDIRECT("Evo[Max "&$H$3&"]")=$H27)*(INDIRECT("Evo[Max "&$H$3&"]")>0)),$G27)),"")}
G28: 4 | H28: =_xlfn.MAXIFS(INDIRECT("Evo[Max "&$H$3&"]"),INDIRECT("Evo[Max "&$H$3&"]"),"<"&$H$20,INDIRECT("Evo[Max "&$H$3&"]"),">0") | I28: {=IFERROR(INDEX(Evo[Evolution_Name],_xlfn.AGGREGATE(15,6,(ROW(Evo[Evolution_Name])-MIN(ROW(Evo[Evolution_Name]))+1)/((INDIRECT("Evo[Max "&$H$3&"]")=$H28)*(INDIRECT("Evo[Max "&$H$3&"]")>0)),$G28)),"")} | J28: {=IFERROR(INDEX(INDIRECT("Evo[+ "&$H$3&"]"),_xlfn.AGGREGATE(15,6,(ROW(Evo[Evolution_Name])-MIN(ROW(Evo[Evolution_Name]))+1)/((INDIRECT("Evo[Max "&$H$3&"]")=$H28)*(INDIRECT("Evo[Max "&$H$3&"]")>0)),$G28)),"")} | K28: {=IFERROR(INDEX(INDIRECT("Evo[+ OVR]"),_xlfn.AGGREGATE(15,6,(ROW(Evo[Evolution_Name])-MIN(ROW(Evo[Evolution_Name]))+1)/((INDIRECT("Evo[Max "&$H$3&"]")=$H28)*(INDIRECT("Evo[Max "&$H$3&"]")>0)),$G28)),"")} | L28: {=IFERROR(INDEX(INDIRECT("Evo[Max OVR]"),_xlfn.AGGREGATE(15,6,(ROW(Evo[Evolution_Name])-MIN(ROW(Evo[Evolution_Name]))+1)/((INDIRECT("Evo[Max "&$H$3&"]")=$H28)*(INDIRECT("Evo[Max "&$H$3&"]")>0)),$G28)),"")} | M28: {=IFERROR(INDEX(INDIRECT("Evo[Req_Position]"),_xlfn.AGGREGATE(15,6,(ROW(Evo[Evolution_Name])-MIN(ROW(Evo[Evolution_Name]))+1)/((INDIRECT("Evo[Max "&$H$3&"]")=$H28)*(INDIRECT("Evo[Max "&$H$3&"]")>0)),$G28)),"")} | N28: {=IFERROR(INDEX(INDIRECT("Evo[Req_OVR_Max]"),_xlfn.AGGREGATE(15,6,(ROW(Evo[Evolution_Name])-MIN(ROW(Evo[Evolution_Name]))+1)/((INDIRECT("Evo[Max "&$H$3&"]")=$H28)*(INDIRECT("Evo[Max "&$H$3&"]")>0)),$G28)),"")} | O28: {=IFERROR(INDEX(INDIRECT("Evo[Req_Other]"),_xlfn.AGGREGATE(15,6,(ROW(Evo[Evolution_Name])-MIN(ROW(Evo[Evolution_Name]))+1)/((INDIRECT("Evo[Max "&$H$3&"]")=$H28)*(INDIRECT("Evo[Max "&$H$3&"]")>0)),$G28)),"")}
G29: 5 | H29: =_xlfn.MAXIFS(INDIRECT("Evo[Max "&$H$3&"]"),INDIRECT("Evo[Max "&$H$3&"]"),"<"&$H$20,INDIRECT("Evo[Max "&$H$3&"]"),">0") | I29: {=IFERROR(INDEX(Evo[Evolution_Name],_xlfn.AGGREGATE(15,6,(ROW(Evo[Evolution_Name])-MIN(ROW(Evo[Evolution_Name]))+1)/((INDIRECT("Evo[Max "&$H$3&"]")=$H29)*(INDIRECT("Evo[Max "&$H$3&"]")>0)),$G29)),"")} | J29: {=IFERROR(INDEX(INDIRECT("Evo[+ "&$H$3&"]"),_xlfn.AGGREGATE(15,6,(ROW(Evo[Evolution_Name])-MIN(ROW(Evo[Evolution_Name]))+1)/((INDIRECT("Evo[Max "&$H$3&"]")=$H29)*(INDIRECT("Evo[Max "&$H$3&"]")>0)),$G29)),"")} | K29: {=IFERROR(INDEX(INDIRECT("Evo[+ OVR]"),_xlfn.AGGREGATE(15,6,(ROW(Evo[Evolution_Name])-MIN(ROW(Evo[Evolution_Name]))+1)/((INDIRECT("Evo[Max "&$H$3&"]")=$H29)*(INDIRECT("Evo[Max "&$H$3&"]")>0)),$G29)),"")} | L29: {=IFERROR(INDEX(INDIRECT("Evo[Max OVR]"),_xlfn.AGGREGATE(15,6,(ROW(Evo[Evolution_Name])-MIN(ROW(Evo[Evolution_Name]))+1)/((INDIRECT("Evo[Max "&$H$3&"]")=$H29)*(INDIRECT("Evo[Max "&$H$3&"]")>0)),$G29)),"")} | M29: {=IFERROR(INDEX(INDIRECT("Evo[Req_Position]"),_xlfn.AGGREGATE(15,6,(ROW(Evo[Evolution_Name])-MIN(ROW(Evo[Evolution_Name]))+1)/((INDIRECT("Evo[Max "&$H$3&"]")=$H29)*(INDIRECT("Evo[Max "&$H$3&"]")>0)),$G29)),"")} | N29: {=IFERROR(INDEX(INDIRECT("Evo[Req_OVR_Max]"),_xlfn.AGGREGATE(15,6,(ROW(Evo[Evolution_Name])-MIN(ROW(Evo[Evolution_Name]))+1)/((INDIRECT("Evo[Max "&$H$3&"]")=$H29)*(INDIRECT("Evo[Max "&$H$3&"]")>0)),$G29)),"")} | O29: {=IFERROR(INDEX(INDIRECT("Evo[Req_Other]"),_xlfn.AGGREGATE(15,6,(ROW(Evo[Evolution_Name])-MIN(ROW(Evo[Evolution_Name]))+1)/((INDIRECT("Evo[Max "&$H$3&"]")=$H29)*(INDIRECT("Evo[Max "&$H$3&"]")>0)),$G29)),"")}
